Workbook

Sheet FL5_MP POR_POR Link
O1: R
B2: Pjt | C2: Year | D2: 2022Y | I2: 2023
C3: Month | D3: Aug. | E3: Sep. | F3: Oct. | G3: Nov. | H3: Dec. | I3: Jan. | J3: Feb. | K3: Mar. | L3: Apr. | M3: May | N3: Jun. | P3: Jul. | Q3: Aug.
B4: =TK4_PVT_BM!E3 -> #REF! | C4: Plan (20221016 udpate) | D4: PROTO 1.0 | F4: PROTO 1.1 | H4: EVT1.0 | J4: EVT 1.1 | L4: DVT | N4: PVT | P4: MP (IOQ3)
D5: SMT Qty | E5: FATP Qty | F5: SMT Qty | G5: FATP Qty | H5: SMT Qty | I5: FATP Qty | J5: SMT Qty | K5: FATP Qty | L5: SMT Qty | M5: FATP Qty | N5: SMT Qty | O5: FATP Qty | P5: SMT Qty | Q5: FATP Qty
D6: 2,900 => 2,488 | E6: 2,150 => 1,292 | F6: 2,100 => 1,656 | G6: 1,600 => 1,173 | H6: 5650 => 4,828 | I6: 4850 => 3,700 | J6: 5300 => 4,830 | K6: 4600 => 4,000 | L6: 11500 => 8,416 | M6: 10784 => 7,275 | N6: 2100 | O6: 2000
D7: SMT | E7: Date | F7: SMT | G7: Date | H7: SMT | I7: Date | J7: SMT | K7: Date | L7: SMT | M7: Date | N7: SMT | O7: Date | P7: SMT | Q7: Date
D8: MIH | E8: =if(isblank(E9),"",_xlfn.WORKDAY.INTL(E9,-7,11)) -> 44778 | F8: MIH | G8: 44826 | H8: MIH | I8: =if(isblank(I9),"",_xlfn.WORKDAY.INTL(I9,-7,11)) -> 44912 | J8: MIH | K8: 44974 | L8: MIH | M8: 45016 | N8: MIH | O8: =if(isblank(O9),"",_xlfn.WORKDAY.INTL(O9,-7,11)) | P8: MIH | Q8: =if(isblank(Q9),"",_xlfn.WORKDAY.INTL(Q9,-7,11))
D9: FBU | E9: 44786 | F9: FBU | G9: 09/30 => 10/13 | H9: FBU | I9: 44921 | J9: FBU | K9: 44982 | L9: FBU | M9: 04/08 => 04/17 | N9: FBU | P9: FBU
D10: SOP | E10: 44797 | F10: SOP | G10: 10/12 => No | H10: SOP | I10: No | J10: SOP | K10: 03/01 => No | L10: SOP | M10: 04/19 => No | N10: SOP | P10: SOP
D11: MINI | E11: 44802 | F11: MINI | G11: 44851 | H11: MINI | I11: 44564 | J11: MINI | K11: 44991 | L11: MINI | M11: 04/24 => 05/02 | N11: MINI | O11: 44731 | P11: MINI | Q11: 44759
D12: MAIN | E12: 44809 | F12: MAIN | G12: 44858 | H12: MAIN | I12: 44935 | J12: MAIN | K12: 44993 | L12: MAIN | M12: 05/01 => 05/08 | N12: MAIN | P12: MAIN
D13: FATP | E13: Date | F13: FATP | G13: Date | H13: FATP | I13: Date | J13: FATP | K13: Date | L13: FATP | M13: Date | N13: FATP | O13: Date | P13: FATP | Q13: Date
D14: MIH | E14: =if(isblank(E15),"",_xlfn.WORKDAY.INTL(E15,-7,11)) -> 44779 | F14: MIH | G14: 44832 | H14: MIH | I14: =if(isblank(I15),"",_xlfn.WORKDAY.INTL(I15,-7,11)) -> 44908 | J14: MIH | K14: 44610 | L14: MIH | M14: 44658 | N14: MIH | O14: =if(isblank(O15),"",_xlfn.WORKDAY.INTL(O15,-7,11)) | P14: MIH | Q14: =if(isblank(Q15),"",_xlfn.WORKDAY.INTL(Q15,-7,11)) -> 44779
D15: FBU | E15: 44788 | F15: FBU | G15: 10/06 => 10/10 | H15: FBU | I15: 44916 | J15: FBU | K15: 44618 | L15: FBU | M15: 04/15 => 04/17 | N15: FBU | P15: FBU | Q15: 44788
D16: SOP | E16: 08/26 => no | F16: SOP | G16: 10/13 => no | H16: SOP | I16: No | J16: SOP | K16: 03/04 => No | L16: SOP | M16: 04/21 => No | N16: SOP | P16: SOP
D17: MINI | E17: 08/30 =>09/01 | F17: MINI | G17: 44851 | H17: MINI | I17: 44566 | J17: MINI | K17: 44628 | L17: MINI | M17: 04/25 => 05/02 | N17: MINI | P17: MINI
D18: MAIN | E18: 09/07 => 09/13 | F18: MAIN | G18: 10/26 => 10/21 | H18: MAIN | I18: 44937 | J18: MAIN | K18: 45000 | L18: MAIN | M18: 05/03 => 05/08 | N18: MAIN | P18: MAIN | Q18: 44804
D19: Distro (Pack) | E19: 44825 | F19: Distro (Pack) | G19: 44874 | H19: Distro (Pack) | I19: 44598 | J19: Distro (Pack) | K19: 44649 | L19: Distro (Pack) | M19: 44698 | N19: Distro (Pack) | P19: Distro (Pack) | Q19: 44806
B21: Build Key Docs | F21: Owner | I21: Shipment & Material Request | M21: Owner | P21: Packing Related Management | T21: Owner
B22: [EXT] FL5 FIH PRQ/CR Tracker List | F22: G_OPM/Frank Bao | I22: [EXT] FL5 SZ MP Ship-to-File | M22: G_OPM/Eva Zhang | P22: [EXT] FL5 MPS | T22: G_BPM/ravigodavarkar@google.com
B23: [EXT] FL5 SKU Matrix | F23: G_PLM/Diana Coker | I23: [EXT] FL5 SZ MP Device Request Table | M23: G_OPM/Eva Zhang | P23: [EXT] FL5 IOQ Tracker | T23: FIH_PC/蘇信軍
B24: [INT] FL5 PVT/MP Build Plan & Build Configs | F24: FIH_EPM/Dobby Lin | I24: [EXT] P24 PVT FATP CTB | M24: FIH_MPM/黃建
B25: [EXT] FL5 LH MP WIP Tracker -DOE | F25: FIH_OPM/Rita Qiu Vicky Chen | I25: [EXT] [P24] TK4/CM4/KM4 (PVT/Ramp) FBU/LBU/PKG Demand | M25: G_MPM/Sunny Xiao
I26: [EXT] P24 KM4/CM4/TK4 MIH | M26: FIH_MPM/alvincs hsu | P26: [EXT] FL5 SZ MP Retail/Carton/Pallet Labels Approval Tracking List | T26: G_Sustpm/John Zhu
B27: [EXT] FL5 Master Equipment List | F27: G_OPM/Frank Bao | P27: [EXT] FL5 VN MP Retail/Carton/Pallet Labels Approval Tracking List | T27: G_Sustpm/Leon Tsai
B28: [INT] FL5 PVT/MP EC Tracker | F28: FIH_EPM/Dobby Lin | I28: [EXT] FL5 Key Allocation Tracker (TAC Range) | M28: G_TE/Jay Wang
B29: [EXT] FL5_PVT/MP_EAN & UPC & cSKU List | F29: G_PLM/Diana Coker / vermaradhika@google.com | P29: [EXT] SZ FL5 - Retail PKG FAI&PFOL + SW FAI +Carrier FAI Tracker | T29: G_OPM/Lehman Lee
B30: [EXT] FL5 LH Line Qual Ramp Master Chart Share with FIH | F30: G_SysTPM/Amy Ma | I30: [EXT] FL5 master data | M30: G/@hcliw@google.com | P30: [EXT] SZ BZ5 - Retail PKG FAI&PFOL + SW FAI +Carrier FAI Tracker | T30: G_OPM/Emma Pai
I31: [EXT] BZ5 master data | M31: G/@hcliw@google.com | P31: [EXT] SZ MT5 - Retail PKG FAI&PFOL + SW FAI +Carrier FAI Tracker | T31: G_OPM/Sean Ao
I32: [EXT] MT5 master data | M32: G/@hcliw@google.com
P34: [EXT] BZ5 SZ MP Retail/Carton/Pallet Labels Approval Tracking List
P35: [EXT] BZ5 VN MP Retail/Carton/Pallet Labels Approval Tracking List | T35: G_Sustpm/Leon Tsai
P37: [EXT] MT5 SZ MP Retail/Carton/Pallet Labels Approval Tracking List
B38: Yield Dashboard & MIL | F38: Owner | P38: [EXT] MT5 VN MP Retail/Carton/Pallet Labels Approval Tracking List | T38: G_Sustpm/Leon Tsai
B39: [EXT] TK4 DOE Request | F39: G_SysTPM/kanchin@ | P39: [EXT] FIH VN & LH_DL Working Hours | T39: FIH_EPM/HeroKLChen@ & KevinKALu@
B40: [EXT] CM4 DOE Request | F40: G_SysTPM/kanchin@ | P40: [INT] P23 NPI build est 220412(Submitted) | T40: FIH_BPM/HarmokoRoni@
P41: [EXT] zNext 訓練教材 【2022/05/31 G officially train FIH】 | T41: G_PLM/dabylin@
P42: [INT] Foxconn zNext access apply list | T42: FIH_EPM/blancoychuang@
P43: [INT] IDM1(F7)辦公區無線上網申請表-TPE | T43: FIH_EPM/blancoychuang@
...

Sheet FL5_POR_包裝對照表 Release Note
B1: DRI: Hero Chen (EPM)/Canny Zhou (LH OPM) / Jenna Thanh Tam (VN OPM)
B3: Version | C3: Date | D3: Change Description | E3: Author | F3: Remark
B4: V29 | C4: 45951 | D4: 更新MAC WIFI 號段（R欄位） | E4: OPM: Canny zhou | F4: 龍華地區
B5: V28 | C5: 45915 | D5: 9/15 Cut in SW Sepr EMR apply for all SKU (117 SKU) : BD3A.250721.001.E1 | E5: OPM: Jenna
B6: V27 | C6: 45915 | D6: 9/15號 導入軟體:BD3A.250721.001.E1 | E6: OPM: Canny zhou | F6: 龍華地區
B7: V26 | C7: 45908 | D7: Adding new IMEI (TAC range) 300K for FL5 VN NA Start range: 35 676628 340000x End range: 35 676628 639999x Old range: Start range: 35 676628 040000x End range: 35 676628 999999x | E7: OPM: Jenna
B8: V25 | C8: 45903 | D8: Cut in CA BOB AW rev C (8 SKU) | E8: OPM: Jenna | F8: ECO
B9: V24 | C9: 45902 | D9: 更新WIFI MAC 號段（Q&R欄位） | E9: OPM: Canny zhou | F9: 龍華地區
B10: V23 | C10: 45901 | D10: MP -CA料號 更新AQ欄位BOB圖檔 RvC，9/1號白班開始導入C版BOB圖檔 | E10: OPM: Canny zhou | F10: 龍華地區
B11: V22 | C11: 45898 | D11: 更新 ROW出貨地 IMEI | E11: OPM: Canny zhou | F11: 龍華地區
B12: V21 | C12: 45843 | D12: 更新 JP 出貨地 IMEI | E12: OPM: Canny zhou | F12: 龍華地區
B13: V17 | C13: 45877 | D13: 更新WIFI MAC 號段（Q&R欄位）及ROW地址 IMEI | E13: OPM: Canny zhou | F13: 龍華地區
B14: V20 | C14: 45861 | D14: FL5 VN MAC range adding 500K New: Start range: B0:D5:FB:C6:60:70 End range: B0:D5:FB:CE:01:8F Old range: Start range: 64:9D:38:32:91:82 End range: 64:9D:38:37:25:61 | E14: OPM: Jenna
B15: V19 | C15: 45859 | D15: 7/21 cut in FRC_VZW regression in packing and zombie line ( 18sku) :BD1A.250702.001.A3 | E15: OPM: Jenna
B16: V18 | C16: 45857 | D16: 7/21號 導入FRC_VZW regression 軟體:BD1A.250702.001.A3 | E16: OPM: Canny zhou | F16: 龍華地區
B17: V17 | C17: 45856 | D17: 更新WIFI MAC 號段（Q&R欄位） | E17: OPM: Canny zhou | F17: 龍華地區
B18: V16 | C18: 45855 | D18: 7/17號 導入 VZW FRC packing line 軟體:BD1A.250702.001 & ROW IMEI | E18: OPM: Canny zhou | F18: 龍華地區
B19: V15 | C19: 45848 | D19: 7/10 VN cut in 117x SKU with FRC SW in packing line :BD1A.250702.001 + 12x SKU in Zombie line | E19: OPM: Jenna | F19: 龍華地區
B20: V14 | C20: 45847 | D20: 7/10號 導入non VZW FRC packing line 軟體:BD1A.250702.001 | E20: OPM: Canny zhou | F20: 龍華地區
B21: V13 | C21: 45846 | D21: 導入non VZW FRC Zombie 軟體:BD1A.250702.001 | E21: OPM: Canny zhou | F21: 龍華地區
B22: V12 | C22: 45843 | D22: 更新 JP 出貨地 IMEI | E22: OPM: Canny zhou | F22: 龍華地區
B23: V10 | C23: 45838 | D23: MP IN/JP料號 更新AQ欄位 retail 圖檔 RvB，6/30號白班開始導入B 版retai 圖檔 | E23: OPM: Canny zhou | F23: 龍華地區
B24: V09 | C24: 45835 | D24: 更新 ROW 出貨地 IMEI &所有料號WIFI 範圍 | E24: OPM: Canny zhou | F24: 龍華地區
B25: V08 | C25: 45831 | D25: Cut in SW RC for 80sku (retai + CLRN) for FL5 VN. BD1A.250527.003.A5 Android 16 | E25: OPM: Jenna
B26: V07 | C26: 45832 | D26: 更新部分DEMO 及精品機大箱標籤（BA欄位） | E26: OPM: Canny zhou | F26: 龍華地區
B27: V06 | C27: 45826 | D27: 更新WIFI MAC 號段（Q&R欄位） | E27: OPM: Canny zhou | F27: 龍華地區
B28: V05 | C28: 45824 | D28: MP GB料號 更新AQ欄位 retail 圖檔 RvB，6/16號導入B 版retai 圖檔 | E28: OPM: Canny zhou | F28: 龍華地區
B29: V04 | C29: 45820 | D29: (1) Update Description內容 (AC column) for all Sales SKUs (2) Update External Color Name (J column) for all Sales SKUs | E29: EPM:Hero Chen | F29: both for VN and LH.
B30: V03 | C30: 45814 | D30: 導入RC 軟體版本：BD1A.250527.003.A5 | E30: OPM: Canny zhou | F30: 龍華地區
B31: V02 | C31: 45801 | D31: Initial | E31: OPM: Canny zhou
B32: V01 | C32: 45797 | D32: Initial | E32: EPM:Hero Chen

Sheet FL5_POR_包裝對照表 (Mapping Table)
B1: DRI: Hero Chen (EPM)/Miya Huang (OPM)
B2: DRI: Hero Chen (EPM)/Canny Zhou (LH OPM) / Jenna Thanh Tam (VN OPM)
C3: Update Date | D3: 45820 | F3: Stage
D4: {="("&xlookup(D3,'FL5_POR_包裝對照表 Release Note'!C:C,'FL5_POR_包裝對照表 Release Note'!B:B,"",0,1)&")"} -> (V04) | E4: GFL (FL5) | F4: MP | G4: TTL 生產 SKU QTY: | H4: =SUM(D7:D9)+SUM(F7:F9)+sum(H7:H8) -> 185
C6: Cat. | D6: Config Q'ty | E6: Cat. | F6: Config Q'ty | G6: Cat. | H6: Config Q'ty
C7: Pristine | D7: =countifs($C$12:$D$204,C7)-countifs(C12:C204,$C$7,D12:D204,"Cancel") -> 47 | E7: Press- N (MKG) | F7: =countifs($C$12:$D$204,E7)-countifs(C12:C204,$E$7,D12:D204,"Cancel") -> 16 | G7: Refurb | H7: =countifs($C$12:$D$204,G7)-countifs(C12:C204,$G$7,D12:D204,"Cancel") -> 47 | BM7: 多條件 xlookup =arrayformula(xlookup(BE&E,'IMaster!E7:E&'Master!G7:G,'Master'!AG7:AG,"No demand",0,1)))
C8: IQ (VzW only) | D8: =countifs($C$12:$D$204,C8)-countifs(C12:C204,$C$8,D12:D204,"Cancel") -> 8 | E8: DEMO | F8: =countifs($C$12:$D$204,E8)-countifs(C12:C204,$E$8,D12:D204,"Cancel") -> 14 | G8: Corp ENG NCUs | H8: =countifs($C$12:$D$204,G8) -> 0
C9: CLNR/FRU | D9: =countifs($C$12:$D$204,C9)-countifs(C12:C204,$C$9,D12:D204,"Cancel") -> 33 | E9: NFU | F9: =countifs($C$12:$D$204,E9)-countifs(C12:C204,$E$9,D12:D204,"Cancel") -> 20 | G9: Cancel | H9: =countifs($D$12:$D$204,G9) -> 8 | N9: foxconn-sz | Q9: 04:00:6E:C4:01:C2 | R9: 04:00:6E:C8:95:A1 | S9: foxconn-vn | V9: 64:9D:38:32:91:82 B0:D5:FB:C6:60:70 | W9: 64:9D:38:37:25:61 B0:D5:FB:CE:01:8F | X9: MP1.0 | Z9: Android 16 | AA9: Android 16 | AE9: ATT/TMO/VZN | AG9: ATT/TMO/VZN | AH9: ATT/TMO/VZW | AO9: x | AQ9: SZ Label approve_M | AR9: SZ Label approve_N | AW9: ATT | BD9: SZ Label approve_L | BE9: SZ Label approve_N | BF9: ATT | BM9: CMFIHCN | BN9: CMFIHVN | BO9: CMFIHIN | BP9: SZ Label approve_L | BQ9: SZ Label approve_M
H10: E | K10: N | L10: D | M10: C | N10: z | O10: AH | P10: AI | S10: z | T10: AH | U10: AI | V10: AI | X10: [DRI: SW Ming] | Y10: [zNext] | Z10: DRI: OPM | AA10: DRI: OPM | AD10: [OPM: Canny Zhou] | AE10: [OPM: Canny Zhou] | AF10: [OPM: Jenna Thanh Tam] | AG10: [OPM: Jenna Thanh Tam] | AH10: J | AI10: Dobby_O | AK10: Dobby_Q | AL10: Dobby_M | AM10: Dobby_N | AN10: Dobby_K | AO10: [zNext] | AP10: [zNext] | AQ10: [Formula] | AR10: [Formula] | AU10: [Formula] | AV10: [Formula] | AW10: [PIC: PLM] | AX10: [Pappu_C] | AY10: [Pappu_D] | BA10: [Formula] | BB10: Others_G | BC10: Others_H | BD10: [Formula] | BE10: [Formula] | BF10: [PIC: PLM] | BG10: [IE: 黃曉冉] | BH10: [IE: Mark Wu] | BI10: [PE: 白家鳴] | BK10: [BPM: Ike Hsieh] | BL10: [務務: 李怡夢] | BM10: [SKW BPM] | BN10: [SKW BPM] | BO10: [SKW BPM] | BP10: [Formula] | BQ10: [Formula]
B11: # | C11: Purpose | D11: Packout Type | E11: Sales SKU | F11: SKU Name | G11: P-SKU | H11: RF Type | I11: Color Key | J11: External Color Name | K11: Color ID (SFC/iFUSE) | L11: Model# 產品型號# | M11: TAC Region 出貨地 | N11: LH TAC Range | O11: LH TAC(IMEI) Start Range | P11: LH TAC(IMEI) End Range | Q11: LH WiFi/BT MAC Start Range | R11: LH WiFi/BT MAC End Range | S11: VN TAC Range | T11: VN TAC(IMEI) Start Range | U11: VN TAC(IMEI) End Range | V11: VN WiFi/BT MAC Start Range | W11: VN WiFi/BT MAC End Range | X11: HW Ver. 硬體版本 | Y11: G655 Software | Z11: LH Android Ver. 安卓版本 | AA11: VN Android Ver. 安卓版本 | AB11: Description _20250407 (From zNEXT) (關務備案內容) | AC11: Description_20250612 (From zNEXT) (關務備案內容) | AD11: LH Zombie 出貨軟體 | AE11: LH SW Version 出貨 image 版本 | AF11: VN Zombie 出貨軟體 | AG11: VN SW Version 出貨 image 版本 | AH11: WCC [WiFi Country Code] | AI11: MLB | AJ11: ANT4 (Mic3) | AK11: CLB (Mic1) | AL11: CG | AM11: BG | AN11: GB (XCVR GPN) | AO11: G954 PKG Assy | AP11: G962 Country Kit (Accessry) | AQ11: LH BOB artowrk GPN（MP 使用帶字母版本） | AR11: LH Retail artwok GPN（MP使用字母版本） | AS11: UFS | AT11: eSIM | AU11: Regulatory Engrave 手機中框垃圾桶 | AV11: COO 镭雕 (IN 鐳雕) 手機中框 Made in COO | AW11: cSKU (Carrier SKU) | AX11: UPC Code-12 | AY11: EAN Code-13 | AZ11: Stage | BA11: Unite/Carton 紙箱包裝數量 | BB11: Master Carton Label 卡通標籤 | BC11: Pallet Label 棧板標籤 | BD11: VN BOB artowrk GPN | BE11: VN Retail artwok GPN | BF11: G670 SIM Card in device Sim卡裝手機 | BG11: LH SFC Routing SFC 路由名稱 | BH11: VN SFC Routing SFC 路由名稱 | BI11: 建BOM 並維護SAP日期 | BJ11: 中文 品名 | BK11: 提交核價日期 | BL11: LH 報關預備案 Status | BM11: LH The 1st ex-LH Date (IOQ3+NCU) 第一次出貨目標日 | BN11: VN The 1st ex-LH Date (IOQ3+NCU) 第一次出貨目標日 | BO11: IN The 1st ex-LH Date (IOQ3+NCU) 第一次出貨目標日 | BP11: LH MRP 模板 GPN | BQ11: VN MRP 模板 GPN | BR11: Remark | BS11: Demo mode
B12: 1 | C12: Pristine | D12: Retail Pack | E12: GA09425-US | F12: VZW, US | G12: UVZ | H12: {=xlookup(F12,z_Others!$B$21:$B$45,z_Others!$E$21:$E$45,"",0,1)} -> mmWave | I12: CLR1 | J12: {=if(isblank(E12),"",xlookup(I12,z_Others!$M$17:$M$20,z_Others!$O$17:$O$20,"",0,1))} -> Obsidian | K12: {=xlookup(I12,z_Others!$M$17:$M$20,z_Others!$N$17:$N$20,"",0,1)} -> BLK | L12: {=xlookup(F12,z_Others!$B$21:$B$45,z_Others!$D$21:$D$45,"",0,1)} -> GLBW0 | M12: {=xlookup(F12,z_Others!$B$21:$B$45,z_Others!$C$21:$C$45,"",0,1)} -> VZW | N12: {=if(isblank(E12),"",xlookup($N$9&M12,z_Others!$X$5:$X$17&z_Others!$W$5:$W$17,z_Others!$Z$5:$Z$17,"",0,1))} -> 35560678 | O12: {=if(isblank(E12),"",xlookup($N$9&M12,z_Others!$X$5:$X$17&z_Others!$W$5:$W$17,z_Others!$AH$5:$AH$17,"",0,1))} -> 35 560678 020000x | P12: {=if(isblank(E12),"",xlookup($N$9&M12,z_Others!$X$5:$X$17&z_Others!$W$5:$W$17,z_Others!$AI$5:$AI$17,"",0,1))} -> 35 560678 999999x | Q12: 04:00:6E:C4:01:C2 64:9D:38:C7:BC:9E 64:9D:38:DE:9F:FE 64:9D:38:EC:5B:9E B0:D5:FB:A3:48:10 34:39:16:36:EE:80 B0:D5:FB:DD:43:D0 34:39:16:5D:00:FC 30:E0:44:6D:2C:72 | R12: 04:00:6E:C8:95:A1 64:9D:38:CC:50:7D 64:9D:38:E3:33:DD 64:9D:38:F0:EF:7D B0:D5:FB:AA:E9:2F 34:39:16:3C:A3:6F B0:D5:FB:DF:2F:FF 34:39:16:64:A2:1B 30:E0:44:74:CD:91 | S12: {=if(isblank(E12),"",xlookup($S$9&M12,z_Others!$X$5:$X$17&z_Others!$W$5:$W$17,z_Others!$Z$5:$Z$17,"",0,1))} -> 35931451 | T12: {=if(isblank(E12),"",xlookup($S$9&M12,z_Others!$X$5:$X$17&z_Others!$W$5:$W$17,z_Others!$AH$5:$AH$17,"",0,1))} -> 35 931451 020000x | U12: {=if(isblank(E12),"",xlookup($S$9&M12,z_Others!$X$5:$X$17&z_Others!$W$5:$W$17,z_Others!$AI$5:$AI$17,"",0,1))} -> 35 931451 999999x | V12: =if(isblank(E12),"",$V$9) -> 64:9D:38:32:91:82 B0:D5:FB:C6:60:70 | W12: =if(isblank(E12),"",$W$9) -> 64:9D:38:37:25:61 B0:D5:FB:CE:01:8F | X12: =if(isblank(E12),"",$X$9) -> MP1.0 | Z12: =if(isblank(E12),"",$Z$9) -> Android 16 | AA12: =if(isblank(F12),"",$Z$9) -> Android 16 | AB12: SKU, CLR1, GOOD, MMWAVE, VZW, US, FL5 | AC12: Pixel 10, Obsidian, 128GB, VZW, US | AD12: BD1A.250702.001.A3 | AE12: BD3A.250721.001.E1 | AF12: BD1A.250702.001.A3 | AG12: BD3A.250721.001.E1 | AH12: {=if(isblank(E12),"",xlookup(F12,z_Others!$B$21:$B$45,z_Others!$F$21:$F$45,"TBD",0,1))} -> US | AI12: {=if(isblank(E12),"", xlookup(E12,'Import_FL5_LH_PVTMP_Configs (Do'!E:E,'Import_FL5_LH_PVTMP_Configs (Do'!O:O,"TBD",0,1))} -> G710-07800-01 | AK12: {=if(isblank(E12),"", xlookup(E12,'Import_FL5_LH_PVTMP_Configs (Do'!E:E,'Import_FL5_LH_PVTMP_Configs (Do'!Q:Q,"TBD",0,1))} -> G650-14694-05 | AL12: {=if(isblank(E12),"", xlookup(E12,'Import_FL5_LH_PVTMP_Configs (Do'!E:E,'Import_FL5_LH_PVTMP_Configs (Do'!M:M,"TBD",0,1))} -> G710-07670-01 | AM12: {=if(isblank(E12),"", xlookup(E12,'Import_FL5_LH_PVTMP_Configs (Do'!E:E,'Import_FL5_LH_PVTMP_Configs (Do'!N:N,"TBD",0,1))} -> G730-09533-01 | AN12: {=if(isblank(E12),"", xlookup(E12,'Import_FL5_LH_PVTMP_Configs (Do'!E:E,'Import_FL5_LH_PVTMP_Configs (Do'!K:K,"TBD",0,1))} -> G950-15935-00 | AO12: {=if(isblank(E12),"",XLOOKUP(E12,'FL5_G954 Pkg ASSY (Pkg BOM)'!L:L,'FL5_G954 Pkg ASSY (Pkg BOM)'!G:G,"N/A",0,1))} -> G954-08540-00 | AP12: {=if(isblank(E12),"",xlookup(E12,'FL5_G962 Country kit (Accesorie'!L:L,'FL5_G962 Country kit (Accesorie'!G:G,"N/A",0,1))} -> G962-00511-00 | AQ12: {=if(isblank(E12),"", xlookup(E12,'Import_LH_Label approve'!E:E,'Import_LH_Label approve'!M:M,"",0,1))} -> G990-08380-11-01 G990-08380-11-A | AR12: {=if(isblank(E12),"",xlookup(E12,'Import_LH_Label approve'!E:E,'Import_LH_Label approve'!N:N,"",0,1))} -> G990-08382-11-01 G990-08382-11-A | AS12: 128GB | AT12: =if(isblank(E12),"","Yes") -> Yes | AU12: =if(isblank(E12),"",if(mid(E12,9,2)="GB", "Yes","No")) -> No | AV12: =if(isblank(E12),"",if(mid(E12,9,2)="IN", "Yes","No")) -> No | AX12: 840353926844 | AY12: 0840353926844 | AZ12: {=if(isblank(E12),"", xlookup(E12,Import_FL5_LH_PVT_BM!D:D,Import_FL5_LH_PVT_BM!AK:AK,$F$4,0,1))} -> MP | BA12: =if(isblank(E12),"",if(D12="Retail Pack","Retail_10ct",if(D12="Bulk Pack","Bulk_30ct"))) -> Retail_10ct | BB12: {=if(isblank(E12),"",xlookup(F12,z_Others!$B$21:$B$42,z_Others!$G$21:$G$42,"No",0,1))} -> VZN Master Carton Label | BC12: {=if(isblank(E12),"",xlookup(F12,z_Others!$B$21:$B$42,z_Others!$H$21:$H$42,"No",0,1))} -> VZN Pallet Label (BTS) | BD12: {=if(isblank(E12),"",xlookup(E12,'Import_VN_Label approve'!E:E,'Import_VN_Label approve'!L:L,"N/A",0,1))} -> G990-08482-11-01 G990-08482-11-A | BE12: {=if(isblank(E12),"",xlookup(E12,'Import_VN_Label approve'!E:E,'Import_VN_Label approve'!N:N,"N/A",0,1))} -> G990-08382-11-01 G990-08382-11-A | BG12: FL5-MP-彩盒包 | BH12: FL5-MP-Colorbox | BI12: 45773 | BJ12: {=if(isblank(E12),"", xlookup(D12,z_Others!$B$5:$B$17,z_Others!$C$5:$C$17,"",0,1))} -> 智能手機 | BK12: 45782 | BL12: {=if(isblank(E12),"",xlookup(E12,'FL5_MP POR_LH_報關備案_G950 & GA'!F:F,'FL5_MP POR_LH_報關備案_G950 & GA'!E:E,"No Need",0,1))} -> Close | BM12: {=if(isblank(E12),"",xlookup($BM$9&E12,'Import_FL5 MPS (06.06.25) - Sor'!E8:E334&'Import_FL5 MPS (06.06.25) - Sor'!F8:F334,'Import_FL5 MPS (06.06.25) - Sor'!ES8:ES334,"No demand",0,1))} -> No demand | BN12: {=if(isblank(E12),"",xlookup($BN$9&E12,'Import_FL5 MPS (06.06.25) - Sor'!E8:E334&'Import_FL5 MPS (06.06.25) - Sor'!F8:F334,'Import_FL5 MPS (06.06.25) - Sor'!ES8:ES334,"No demand",0,1))} -> No demand | BO12: {=if(isblank(E12),"",xlookup($BO$9&E12,'Import_FL5 MPS (06.06.25) - Sor'!E8:E334&'Import_FL5 MPS (06.06.25) - Sor'!F8:F334,'Import_FL5 MPS (06.06.25) - Sor'!ES8:ES334,"No demand",0,1))} -> No demand | BP12: {=if(isblank(E12),"", xlookup(E12,'Import_LH_Label approve'!E:E,'Import_LH_Label approve'!L:L,"",0,1))} | BQ12: {=if(isblank(E12),"",xlookup(E12,'Import_VN_Label approve'!E:E,'Import_VN_Label approve'!M:M,"N/A",0,1))}
B13: 2 | C13: Pristine | D13: Retail Pack | E13: GA10238-US | F13: VZW, US | G13: UVZ | H13: {=xlookup(F13,z_Others!$B$21:$B$45,z_Others!$E$21:$E$45,"",0,1)} -> mmWave | I13: CLR2 | J13: {=if(isblank(E13),"",xlookup(I13,z_Others!$M$17:$M$20,z_Others!$O$17:$O$20,"",0,1))} -> Frost | K13: {=xlookup(I13,z_Others!$M$17:$M$20,z_Others!$N$17:$N$20,"",0,1)} -> PPL | L13: {=xlookup(F13,z_Others!$B$21:$B$45,z_Others!$D$21:$D$45,"",0,1)} -> GLBW0 | M13: {=xlookup(F13,z_Others!$B$21:$B$45,z_Others!$C$21:$C$45,"",0,1)} -> VZW | N13: {=if(isblank(E13),"",xlookup($N$9&M13,z_Others!$X$5:$X$17&z_Others!$W$5:$W$17,z_Others!$Z$5:$Z$17,"",0,1))} -> 35560678 | O13: {=if(isblank(E13),"",xlookup($N$9&M13,z_Others!$X$5:$X$17&z_Others!$W$5:$W$17,z_Others!$AH$5:$AH$17,"",0,1))} -> 35 560678 020000x | P13: {=if(isblank(E13),"",xlookup($N$9&M13,z_Others!$X$5:$X$17&z_Others!$W$5:$W$17,z_Others!$AI$5:$AI$17,"",0,1))} -> 35 560678 999999x | Q13: 04:00:6E:C4:01:C2 64:9D:38:C7:BC:9E 64:9D:38:DE:9F:FE 64:9D:38:EC:5B:9E B0:D5:FB:A3:48:10 34:39:16:36:EE:80 B0:D5:FB:DD:43:D0 34:39:16:5D:00:FC 30:E0:44:6D:2C:72 | R13: 04:00:6E:C8:95:A1 64:9D:38:CC:50:7D 64:9D:38:E3:33:DD 64:9D:38:F0:EF:7D B0:D5:FB:AA:E9:2F 34:39:16:3C:A3:6F B0:D5:FB:DF:2F:FF 34:39:16:64:A2:1B 30:E0:44:74:CD:91 | S13: {=if(isblank(E13),"",xlookup($S$9&M13,z_Others!$X$5:$X$17&z_Others!$W$5:$W$17,z_Others!$Z$5:$Z$17,"",0,1))} -> 35931451 | T13: {=if(isblank(E13),"",xlookup($S$9&M13,z_Others!$X$5:$X$17&z_Others!$W$5:$W$17,z_Others!$AH$5:$AH$17,"",0,1))} -> 35 931451 020000x | U13: {=if(isblank(E13),"",xlookup($S$9&M13,z_Others!$X$5:$X$17&z_Others!$W$5:$W$17,z_Others!$AI$5:$AI$17,"",0,1))} -> 35 931451 999999x | V13: =if(isblank(E13),"",$V$9) -> 64:9D:38:32:91:82 B0:D5:FB:C6:60:70 | W13: =if(isblank(E13),"",$W$9) -> 64:9D:38:37:25:61 B0:D5:FB:CE:01:8F | X13: =if(isblank(E13),"",$X$9) -> MP1.0 | Z13: =if(isblank(E13),"",$Z$9) -> Android 16 | AA13: =if(isblank(F13),"",$Z$9) -> Android 16 | AB13: SKU, CLR2, GOOD, MMWAVE, VZW, US, FL5 | AC13: Pixel 10, Frost, 128GB, VZW, US | AD13: BD1A.250702.001.A3 | AE13: BD3A.250721.001.E1 | AF13: BD1A.250702.001.A3 | AG13: BD3A.250721.001.E1 | AH13: {=if(isblank(E13),"",xlookup(F13,z_Others!$B$21:$B$45,z_Others!$F$21:$F$45,"TBD",0,1))} -> US | AI13: {=if(isblank(E13),"", xlookup(E13,'Import_FL5_LH_PVTMP_Configs (Do'!E:E,'Import_FL5_LH_PVTMP_Configs (Do'!O:O,"TBD",0,1))} -> G710-07800-01 | AK13: {=if(isblank(E13),"", xlookup(E13,'Import_FL5_LH_PVTMP_Configs (Do'!E:E,'Import_FL5_LH_PVTMP_Configs (Do'!Q:Q,"TBD",0,1))} -> G650-14694-05 | AL13: {=if(isblank(E13),"", xlookup(E13,'Import_FL5_LH_PVTMP_Configs (Do'!E:E,'Import_FL5_LH_PVTMP_Configs (Do'!M:M,"TBD",0,1))} -> G710-07670-01 | AM13: {=if(isblank(E13),"", xlookup(E13,'Import_FL5_LH_PVTMP_Configs (Do'!E:E,'Import_FL5_LH_PVTMP_Configs (Do'!N:N,"TBD",0,1))} -> G730-09533-02 | AN13: {=if(isblank(E13),"", xlookup(E13,'Import_FL5_LH_PVTMP_Configs (Do'!E:E,'Import_FL5_LH_PVTMP_Configs (Do'!K:K,"TBD",0,1))} -> G950-15935-01 | AO13: {=if(isblank(E13),"",XLOOKUP(E13,'FL5_G954 Pkg ASSY (Pkg BOM)'!L:L,'FL5_G954 Pkg ASSY (Pkg BOM)'!G:G,"N/A",0,1))} -> G954-08540-00 | AP13: {=if(isblank(E13),"",xlookup(E13,'FL5_G962 Country kit (Accesorie'!L:L,'FL5_G962 Country kit (Accesorie'!G:G,"N/A",0,1))} -> G962-00511-00 | AQ13: {=if(isblank(E13),"", xlookup(E13,'Import_LH_Label approve'!E:E,'Import_LH_Label approve'!M:M,"",0,1))} -> G990-08380-21-01 G990-08380-21-A | AR13: {=if(isblank(E13),"",xlookup(E13,'Import_LH_Label approve'!E:E,'Import_LH_Label approve'!N:N,"",0,1))} -> G990-08382-11-01 G990-08382-11-A | AS13: 128GB | AT13: =if(isblank(E13),"","Yes") -> Yes | AU13: =if(isblank(E13),"",if(mid(E13,9,2)="GB", "Yes","No")) -> No | AV13: =if(isblank(E13),"",if(mid(E13,9,2)="IN", "Yes","No")) -> No | AX13: 840353926851 | AY13: 0840353926851 | AZ13: {=if(isblank(E13),"", xlookup(E13,Import_FL5_LH_PVT_BM!D:D,Import_FL5_LH_PVT_BM!AK:AK,$F$4,0,1))} -> MP | BA13: =if(isblank(E13),"",if(D13="Retail Pack","Retail_10ct",if(D13="Bulk Pack","Bulk_30ct"))) -> Retail_10ct | BB13: {=if(isblank(E13),"",xlookup(F13,z_Others!$B$21:$B$42,z_Others!$G$21:$G$42,"No",0,1))} -> VZN Master Carton Label | BC13: {=if(isblank(E13),"",xlookup(F13,z_Others!$B$21:$B$42,z_Others!$H$21:$H$42,"No",0,1))} -> VZN Pallet Label (BTS) | BD13: {=if(isblank(E13),"",xlookup(E13,'Import_VN_Label approve'!E:E,'Import_VN_Label approve'!L:L,"N/A",0,1))} -> G990-08482-21-01 G990-08482-21-A | BE13: {=if(isblank(E13),"",xlookup(E13,'Import_VN_Label approve'!E:E,'Import_VN_Label approve'!N:N,"N/A",0,1))} -> G990-08382-11-01 G990-08382-11-A | BG13: FL5-MP-彩盒包 | BH13: FL5-MP-Colorbox | BI13: 45773 | BJ13: {=if(isblank(E13),"", xlookup(D13,z_Others!$B$5:$B$17,z_Others!$C$5:$C$17,"",0,1))} -> 智能手機 | BK13: 45782 | BL13: {=if(isblank(E13),"",xlookup(E13,'FL5_MP POR_LH_報關備案_G950 & GA'!F:F,'FL5_MP POR_LH_報關備案_G950 & GA'!E:E,"No Need",0,1))} -> Close | BM13: {=if(isblank(E13),"",xlookup($BM$9&E13,'Import_FL5 MPS (06.06.25) - Sor'!E9:E334&'Import_FL5 MPS (06.06.25) - Sor'!F9:F334,'Import_FL5 MPS (06.06.25) - Sor'!ES9:ES334,"No demand",0,1))} -> No demand | BN13: {=if(isblank(E13),"",xlookup($BN$9&E13,'Import_FL5 MPS (06.06.25) - Sor'!E9:E334&'Import_FL5 MPS (06.06.25) - Sor'!F9:F334,'Import_FL5 MPS (06.06.25) - Sor'!ES9:ES334,"No demand",0,1))} -> No demand | BO13: {=if(isblank(E13),"",xlookup($BO$9&E13,'Import_FL5 MPS (06.06.25) - Sor'!E9:E334&'Import_FL5 MPS (06.06.25) - Sor'!F9:F334,'Import_FL5 MPS (06.06.25) - Sor'!ES9:ES334,"No demand",0,1))} -> No demand | BP13: {=if(isblank(E13),"", xlookup(E13,'Import_LH_Label approve'!E:E,'Import_LH_Label approve'!L:L,"",0,1))} | BQ13: {=if(isblank(E13),"",xlookup(E13,'Import_VN_Label approve'!E:E,'Import_VN_Label approve'!M:M,"N/A",0,1))}
B14: 3 | C14: Pristine | D14: Retail Pack | E14: GA10239-US | F14: VZW, US | G14: UVZ | H14: {=xlookup(F14,z_Others!$B$21:$B$45,z_Others!$E$21:$E$45,"",0,1)} -> mmWave | I14: CLR3 | J14: {=if(isblank(E14),"",xlookup(I14,z_Others!$M$17:$M$20,z_Others!$O$17:$O$20,"",0,1))} -> Lemongrass | K14: {=xlookup(I14,z_Others!$M$17:$M$20,z_Others!$N$17:$N$20,"",0,1)} -> YEL | L14: {=xlookup(F14,z_Others!$B$21:$B$45,z_Others!$D$21:$D$45,"",0,1)} -> GLBW0 | M14: {=xlookup(F14,z_Others!$B$21:$B$45,z_Others!$C$21:$C$45,"",0,1)} -> VZW | N14: {=if(isblank(E14),"",xlookup($N$9&M14,z_Others!$X$5:$X$17&z_Others!$W$5:$W$17,z_Others!$Z$5:$Z$17,"",0,1))} -> 35560678 | O14: {=if(isblank(E14),"",xlookup($N$9&M14,z_Others!$X$5:$X$17&z_Others!$W$5:$W$17,z_Others!$AH$5:$AH$17,"",0,1))} -> 35 560678 020000x | P14: {=if(isblank(E14),"",xlookup($N$9&M14,z_Others!$X$5:$X$17&z_Others!$W$5:$W$17,z_Others!$AI$5:$AI$17,"",0,1))} -> 35 560678 999999x | Q14: 04:00:6E:C4:01:C2 64:9D:38:C7:BC:9E 64:9D:38:DE:9F:FE 64:9D:38:EC:5B:9E B0:D5:FB:A3:48:10 34:39:16:36:EE:80 B0:D5:FB:DD:43:D0 34:39:16:5D:00:FC 30:E0:44:6D:2C:72 | R14: 04:00:6E:C8:95:A1 64:9D:38:CC:50:7D 64:9D:38:E3:33:DD 64:9D:38:F0:EF:7D B0:D5:FB:AA:E9:2F 34:39:16:3C:A3:6F B0:D5:FB:DF:2F:FF 34:39:16:64:A2:1B 30:E0:44:74:CD:91 | S14: {=if(isblank(E14),"",xlookup($S$9&M14,z_Others!$X$5:$X$17&z_Others!$W$5:$W$17,z_Others!$Z$5:$Z$17,"",0,1))} -> 35931451 | T14: {=if(isblank(E14),"",xlookup($S$9&M14,z_Others!$X$5:$X$17&z_Others!$W$5:$W$17,z_Others!$AH$5:$AH$17,"",0,1))} -> 35 931451 020000x | U14: {=if(isblank(E14),"",xlookup($S$9&M14,z_Others!$X$5:$X$17&z_Others!$W$5:$W$17,z_Others!$AI$5:$AI$17,"",0,1))} -> 35 931451 999999x | V14: =if(isblank(E14),"",$V$9) -> 64:9D:38:32:91:82 B0:D5:FB:C6:60:70 | W14: =if(isblank(E14),"",$W$9) -> 64:9D:38:37:25:61 B0:D5:FB:CE:01:8F | X14: =if(isblank(E14),"",$X$9) -> MP1.0 | Z14: =if(isblank(E14),"",$Z$9) -> Android 16 | AA14: =if(isblank(F14),"",$Z$9) -> Android 16 | AB14: SKU, CLR3, GOOD, MMWAVE, VZW, US, FL5 | AC14: Pixel 10, Lemongrass, 128GB, VZW, US | AD14: BD1A.250702.001.A3 | AE14: BD3A.250721.001.E1 | AF14: BD1A.250702.001.A3 | AG14: BD3A.250721.001.E1 | AH14: {=if(isblank(E14),"",xlookup(F14,z_Others!$B$21:$B$45,z_Others!$F$21:$F$45,"TBD",0,1))} -> US | AI14: {=if(isblank(E14),"", xlookup(E14,'Import_FL5_LH_PVTMP_Configs (Do'!E:E,'Import_FL5_LH_PVTMP_Configs (Do'!O:O,"TBD",0,1))} -> G710-07800-01 | AK14: {=if(isblank(E14),"", xlookup(E14,'Import_FL5_LH_PVTMP_Configs (Do'!E:E,'Import_FL5_LH_PVTMP_Configs (Do'!Q:Q,"TBD",0,1))} -> G650-14694-05 | AL14: {=if(isblank(E14),"", xlookup(E14,'Import_FL5_LH_PVTMP_Configs (Do'!E:E,'Import_FL5_LH_PVTMP_Configs (Do'!M:M,"TBD",0,1))} -> G710-07670-01 | AM14: {=if(isblank(E14),"", xlookup(E14,'Import_FL5_LH_PVTMP_Configs (Do'!E:E,'Import_FL5_LH_PVTMP_Configs (Do'!N:N,"TBD",0,1))} -> G730-09533-03 | AN14: {=if(isblank(E14),"", xlookup(E14,'Import_FL5_LH_PVTMP_Configs (Do'!E:E,'Import_FL5_LH_PVTMP_Configs (Do'!K:K,"TBD",0,1))} -> G950-15935-02 | AO14: {=if(isblank(E14),"",XLOOKUP(E14,'FL5_G954 Pkg ASSY (Pkg BOM)'!L:L,'FL5_G954 Pkg ASSY (Pkg BOM)'!G:G,"N/A",0,1))} -> G954-08540-00 | AP14: {=if(isblank(E14),"",xlookup(E14,'FL5_G962 Country kit (Accesorie'!L:L,'FL5_G962 Country kit (Accesorie'!G:G,"N/A",0,1))} -> G962-00511-00 | AQ14: {=if(isblank(E14),"", xlookup(E14,'Import_LH_Label approve'!E:E,'Import_LH_Label approve'!M:M,"",0,1))} -> G990-08380-31-02 G990-08380-31-A | AR14: {=if(isblank(E14),"",xlookup(E14,'Import_LH_Label approve'!E:E,'Import_LH_Label approve'!N:N,"",0,1))} -> G990-08382-11-01 G990-08382-11-A | AS14: 128GB | AT14: =if(isblank(E14),"","Yes") -> Yes | AU14: =if(isblank(E14),"",if(mid(E14,9,2)="GB", "Yes","No")) -> No | AV14: =if(isblank(E14),"",if(mid(E14,9,2)="IN", "Yes","No")) -> No | AX14: 840353926875 | AY14: 0840353926875 | AZ14: {=if(isblank(E14),"", xlookup(E14,Import_FL5_LH_PVT_BM!D:D,Import_FL5_LH_PVT_BM!AK:AK,$F$4,0,1))} -> MP | BA14: =if(isblank(E14),"",if(D14="Retail Pack","Retail_10ct",if(D14="Bulk Pack","Bulk_30ct"))) -> Retail_10ct | BB14: {=if(isblank(E14),"",xlookup(F14,z_Others!$B$21:$B$42,z_Others!$G$21:$G$42,"No",0,1))} -> VZN Master Carton Label | BC14: {=if(isblank(E14),"",xlookup(F14,z_Others!$B$21:$B$42,z_Others!$H$21:$H$42,"No",0,1))} -> VZN Pallet Label (BTS) | BD14: {=if(isblank(E14),"",xlookup(E14,'Import_VN_Label approve'!E:E,'Import_VN_Label approve'!L:L,"N/A",0,1))} -> G990-08482-31-01 G990-08482-31-A | BE14: {=if(isblank(E14),"",xlookup(E14,'Import_VN_Label approve'!E:E,'Import_VN_Label approve'!N:N,"N/A",0,1))} -> G990-08382-11-01 G990-08382-11-A | BG14: FL5-MP-彩盒包 | BH14: FL5-MP-Colorbox | BI14: 45773 | BJ14: {=if(isblank(E14),"", xlookup(D14,z_Others!$B$5:$B$17,z_Others!$C$5:$C$17,"",0,1))} -> 智能手機 | BK14: 45765 | BL14: {=if(isblank(E14),"",xlookup(E14,'FL5_MP POR_LH_報關備案_G950 & GA'!F:F,'FL5_MP POR_LH_報關備案_G950 & GA'!E:E,"No Need",0,1))} -> Close | BM14: {=if(isblank(E14),"",xlookup($BM$9&E14,'Import_FL5 MPS (06.06.25) - Sor'!E10:E334&'Import_FL5 MPS (06.06.25) - Sor'!F10:F334,'Import_FL5 MPS (06.06.25) - Sor'!ES10:ES334,"No demand",0,1))} -> No demand | BN14: {=if(isblank(E14),"",xlookup($BN$9&E14,'Import_FL5 MPS (06.06.25) - Sor'!E10:E334&'Import_FL5 MPS (06.06.25) - Sor'!F10:F334,'Import_FL5 MPS (06.06.25) - Sor'!ES10:ES334,"No demand",0,1))} -> No demand | BO14: {=if(isblank(E14),"",xlookup($BO$9&E14,'Import_FL5 MPS (06.06.25) - Sor'!E10:E334&'Import_FL5 MPS (06.06.25) - Sor'!F10:F334,'Import_FL5 MPS (06.06.25) - Sor'!ES10:ES334,"No demand",0,1))} -> No demand | BP14: {=if(isblank(E14),"", xlookup(E14,'Import_LH_Label approve'!E:E,'Import_LH_Label approve'!L:L,"",0,1))} | BQ14: {=if(isblank(E14),"",xlookup(E14,'Import_VN_Label approve'!E:E,'Import_VN_Label approve'!M:M,"N/A",0,1))}
B15: 4 | C15: Pristine | D15: Retail Pack | E15: GA10240-US | F15: VZW, US | G15: UVZ | H15: {=xlookup(F15,z_Others!$B$21:$B$45,z_Others!$E$21:$E$45,"",0,1)} -> mmWave | I15: CLR4 | J15: {=if(isblank(E15),"",xlookup(I15,z_Others!$M$17:$M$20,z_Others!$O$17:$O$20,"",0,1))} -> Indigo | K15: {=xlookup(I15,z_Others!$M$17:$M$20,z_Others!$N$17:$N$20,"",0,1)} -> BUE | L15: {=xlookup(F15,z_Others!$B$21:$B$45,z_Others!$D$21:$D$45,"",0,1)} -> GLBW0 | M15: {=xlookup(F15,z_Others!$B$21:$B$45,z_Others!$C$21:$C$45,"",0,1)} -> VZW | N15: {=if(isblank(E15),"",xlookup($N$9&M15,z_Others!$X$5:$X$17&z_Others!$W$5:$W$17,z_Others!$Z$5:$Z$17,"",0,1))} -> 35560678 | O15: {=if(isblank(E15),"",xlookup($N$9&M15,z_Others!$X$5:$X$17&z_Others!$W$5:$W$17,z_Others!$AH$5:$AH$17,"",0,1))} -> 35 560678 020000x | P15: {=if(isblank(E15),"",xlookup($N$9&M15,z_Others!$X$5:$X$17&z_Others!$W$5:$W$17,z_Others!$AI$5:$AI$17,"",0,1))} -> 35 560678 999999x | Q15: 04:00:6E:C4:01:C2 64:9D:38:C7:BC:9E 64:9D:38:DE:9F:FE 64:9D:38:EC:5B:9E B0:D5:FB:A3:48:10 34:39:16:36:EE:80 B0:D5:FB:DD:43:D0 34:39:16:5D:00:FC 30:E0:44:6D:2C:72 | R15: 04:00:6E:C8:95:A1 64:9D:38:CC:50:7D 64:9D:38:E3:33:DD 64:9D:38:F0:EF:7D B0:D5:FB:AA:E9:2F 34:39:16:3C:A3:6F B0:D5:FB:DF:2F:FF 34:39:16:64:A2:1B 30:E0:44:74:CD:91 | S15: {=if(isblank(E15),"",xlookup($S$9&M15,z_Others!$X$5:$X$17&z_Others!$W$5:$W$17,z_Others!$Z$5:$Z$17,"",0,1))} -> 35931451 | T15: {=if(isblank(E15),"",xlookup($S$9&M15,z_Others!$X$5:$X$17&z_Others!$W$5:$W$17,z_Others!$AH$5:$AH$17,"",0,1))} -> 35 931451 020000x | U15: {=if(isblank(E15),"",xlookup($S$9&M15,z_Others!$X$5:$X$17&z_Others!$W$5:$W$17,z_Others!$AI$5:$AI$17,"",0,1))} -> 35 931451 999999x | V15: =if(isblank(E15),"",$V$9) -> 64:9D:38:32:91:82 B0:D5:FB:C6:60:70 | W15: =if(isblank(E15),"",$W$9) -> 64:9D:38:37:25:61 B0:D5:FB:CE:01:8F | X15: =if(isblank(E15),"",$X$9) -> MP1.0 | Z15: =if(isblank(E15),"",$Z$9) -> Android 16 | AA15: =if(isblank(F15),"",$Z$9) -> Android 16 | AB15: SKU, CLR4, GOOD, MMWAVE, VZW, US, FL5 | AC15: Pixel 10, Indigo, 128GB, VZW, US | AD15: BD1A.250702.001.A3 | AE15: BD3A.250721.001.E1 | AF15: BD1A.250702.001.A3 | AG15: BD3A.250721.001.E1 | AH15: {=if(isblank(E15),"",xlookup(F15,z_Others!$B$21:$B$45,z_Others!$F$21:$F$45,"TBD",0,1))} -> US | AI15: {=if(isblank(E15),"", xlookup(E15,'Import_FL5_LH_PVTMP_Configs (Do'!E:E,'Import_FL5_LH_PVTMP_Configs (Do'!O:O,"TBD",0,1))} -> G710-07800-01 | AK15: {=if(isblank(E15),"", xlookup(E15,'Import_FL5_LH_PVTMP_Configs (Do'!E:E,'Import_FL5_LH_PVTMP_Configs (Do'!Q:Q,"TBD",0,1))} -> G650-14694-05 | AL15: {=if(isblank(E15),"", xlookup(E15,'Import_FL5_LH_PVTMP_Configs (Do'!E:E,'Import_FL5_LH_PVTMP_Configs (Do'!M:M,"TBD",0,1))} -> G710-07670-01 | AM15: {=if(isblank(E15),"", xlookup(E15,'Import_FL5_LH_PVTMP_Configs (Do'!E:E,'Import_FL5_LH_PVTMP_Configs (Do'!N:N,"TBD",0,1))} -> G730-09533-04 | AN15: {=if(isblank(E15),"", xlookup(E15,'Import_FL5_LH_PVTMP_Configs (Do'!E:E,'Import_FL5_LH_PVTMP_Configs (Do'!K:K,"TBD",0,1))} -> G950-15935-03 | AO15: {=if(isblank(E15),"",XLOOKUP(E15,'FL5_G954 Pkg ASSY (Pkg BOM)'!L:L,'FL5_G954 Pkg ASSY (Pkg BOM)'!G:G,"N/A",0,1))} -> G954-08540-00 | AP15: {=if(isblank(E15),"",xlookup(E15,'FL5_G962 Country kit (Accesorie'!L:L,'FL5_G962 Country kit (Accesorie'!G:G,"N/A",0,1))} -> G962-00511-00 | AQ15: {=if(isblank(E15),"", xlookup(E15,'Import_LH_Label approve'!E:E,'Import_LH_Label approve'!M:M,"",0,1))} -> G990-08380-41-01 G990-08380-41-A | AR15: {=if(isblank(E15),"",xlookup(E15,'Import_LH_Label approve'!E:E,'Import_LH_Label approve'!N:N,"",0,1))} -> G990-08382-11-01 G990-08382-11-A | AS15: 128GB | AT15: =if(isblank(E15),"","Yes") -> Yes | AU15: =if(isblank(E15),"",if(mid(E15,9,2)="GB", "Yes","No")) -> No | AV15: =if(isblank(E15),"",if(mid(E15,9,2)="IN", "Yes","No")) -> No | AX15: 840353926868 | AY15: 0840353926868 | AZ15: {=if(isblank(E15),"", xlookup(E15,Import_FL5_LH_PVT_BM!D:D,Import_FL5_LH_PVT_BM!AK:AK,$F$4,0,1))} -> MP | BA15: =if(isblank(E15),"",if(D15="Retail Pack","Retail_10ct",if(D15="Bulk Pack","Bulk_30ct"))) -> Retail_10ct | BB15: {=if(isblank(E15),"",xlookup(F15,z_Others!$B$21:$B$42,z_Others!$G$21:$G$42,"No",0,1))} -> VZN Master Carton Label | BC15: {=if(isblank(E15),"",xlookup(F15,z_Others!$B$21:$B$42,z_Others!$H$21:$H$42,"No",0,1))} -> VZN Pallet Label (BTS) | BD15: {=if(isblank(E15),"",xlookup(E15,'Import_VN_Label approve'!E:E,'Import_VN_Label approve'!L:L,"N/A",0,1))} -> G990-08482-41-01 G990-08482-41-A | BE15: {=if(isblank(E15),"",xlookup(E15,'Import_VN_Label approve'!E:E,'Import_VN_Label approve'!N:N,"N/A",0,1))} -> G990-08382-11-01 G990-08382-11-A | BG15: FL5-MP-彩盒包 | BH15: FL5-MP-Colorbox | BI15: 45773 | BJ15: {=if(isblank(E15),"", xlookup(D15,z_Others!$B$5:$B$17,z_Others!$C$5:$C$17,"",0,1))} -> 智能手機 | BK15: 45765 | BL15: {=if(isblank(E15),"",xlookup(E15,'FL5_MP POR_LH_報關備案_G950 & GA'!F:F,'FL5_MP POR_LH_報關備案_G950 & GA'!E:E,"No Need",0,1))} -> Close | BM15: {=if(isblank(E15),"",xlookup($BM$9&E15,'Import_FL5 MPS (06.06.25) - Sor'!E11:E334&'Import_FL5 MPS (06.06.25) - Sor'!F11:F334,'Import_FL5 MPS (06.06.25) - Sor'!ES11:ES334,"No demand",0,1))} -> No demand | BN15: {=if(isblank(E15),"",xlookup($BN$9&E15,'Import_FL5 MPS (06.06.25) - Sor'!E11:E334&'Import_FL5 MPS (06.06.25) - Sor'!F11:F334,'Import_FL5 MPS (06.06.25) - Sor'!ES11:ES334,"No demand",0,1))} -> No demand | BO15: {=if(isblank(E15),"",xlookup($BO$9&E15,'Import_FL5 MPS (06.06.25) - Sor'!E11:E334&'Import_FL5 MPS (06.06.25) - Sor'!F11:F334,'Import_FL5 MPS (06.06.25) - Sor'!ES11:ES334,"No demand",0,1))} -> No demand | BP15: {=if(isblank(E15),"", xlookup(E15,'Import_LH_Label approve'!E:E,'Import_LH_Label approve'!L:L,"",0,1))} | BQ15: {=if(isblank(E15),"",xlookup(E15,'Import_VN_Label approve'!E:E,'Import_VN_Label approve'!M:M,"N/A",0,1))}
B16: 5 | C16: Pristine | D16: Retail Pack | E16: GA09861-US | F16: AT&T, US | G16: UAT | H16: {=xlookup(F16,z_Others!$B$21:$B$45,z_Others!$E$21:$E$45,"",0,1)} -> mmWave | I16: CLR1 | J16: {=if(isblank(E16),"",xlookup(I16,z_Others!$M$17:$M$20,z_Others!$O$17:$O$20,"",0,1))} -> Obsidian | K16: {=xlookup(I16,z_Others!$M$17:$M$20,z_Others!$N$17:$N$20,"",0,1)} -> BLK | L16: {=xlookup(F16,z_Others!$B$21:$B$45,z_Others!$D$21:$D$45,"",0,1)} -> GLBW0 | M16: {=xlookup(F16,z_Others!$B$21:$B$45,z_Others!$C$21:$C$45,"",0,1)} -> ATT | N16: {=if(isblank(E16),"",xlookup($N$9&M16,z_Others!$X$5:$X$17&z_Others!$W$5:$W$17,z_Others!$Z$5:$Z$17,"",0,1))} -> 35582324 | O16: {=if(isblank(E16),"",xlookup($N$9&M16,z_Others!$X$5:$X$17&z_Others!$W$5:$W$17,z_Others!$AH$5:$AH$17,"",0,1))} -> 35 582324 020000x | P16: {=if(isblank(E16),"",xlookup($N$9&M16,z_Others!$X$5:$X$17&z_Others!$W$5:$W$17,z_Others!$AI$5:$AI$17,"",0,1))} -> 35 582324 999999x | Q16: 04:00:6E:C4:01:C2 64:9D:38:C7:BC:9E 64:9D:38:DE:9F:FE 64:9D:38:EC:5B:9E B0:D5:FB:A3:48:10 34:39:16:36:EE:80 B0:D5:FB:DD:43:D0 34:39:16:5D:00:FC 30:E0:44:6D:2C:72 | R16: 04:00:6E:C8:95:A1 64:9D:38:CC:50:7D 64:9D:38:E3:33:DD 64:9D:38:F0:EF:7D B0:D5:FB:AA:E9:2F 34:39:16:3C:A3:6F B0:D5:FB:DF:2F:FF 34:39:16:64:A2:1B 30:E0:44:74:CD:91 | S16: {=if(isblank(E16),"",xlookup($S$9&M16,z_Others!$X$5:$X$17&z_Others!$W$5:$W$17,z_Others!$Z$5:$Z$17,"",0,1))} -> 35484520 | T16: {=if(isblank(E16),"",xlookup($S$9&M16,z_Others!$X$5:$X$17&z_Others!$W$5:$W$17,z_Others!$AH$5:$AH$17,"",0,1))} -> 35 484520 020000x | U16: {=if(isblank(E16),"",xlookup($S$9&M16,z_Others!$X$5:$X$17&z_Others!$W$5:$W$17,z_Others!$AI$5:$AI$17,"",0,1))} -> 35 484520 999999x | V16: =if(isblank(E16),"",$V$9) -> 64:9D:38:32:91:82 B0:D5:FB:C6:60:70 | W16: =if(isblank(E16),"",$W$9) -> 64:9D:38:37:25:61 B0:D5:FB:CE:01:8F | X16: =if(isblank(E16),"",$X$9) -> MP1.0 | Z16: =if(isblank(E16),"",$Z$9) -> Android 16 | AA16: =if(isblank(F16),"",$Z$9) -> Android 16 | AB16: SKU, CLR1, GOOD, MMWAVE, AT&T, US, FL5 | AC16: Pixel 10, Obsidian, 128GB, AT&T, US | AD16: BD1A.250702.001 | AE16: BD3A.250721.001.E1 | AF16: BD1A.250702.001 | AG16: BD3A.250721.001.E1 | AH16: {=if(isblank(E16),"",xlookup(F16,z_Others!$B$21:$B$45,z_Others!$F$21:$F$45,"TBD",0,1))} -> US | AI16: {=if(isblank(E16),"", xlookup(E16,'Import_FL5_LH_PVTMP_Configs (Do'!E:E,'Import_FL5_LH_PVTMP_Configs (Do'!O:O,"TBD",0,1))} -> G710-07800-01 | AK16: {=if(isblank(E16),"", xlookup(E16,'Import_FL5_LH_PVTMP_Configs (Do'!E:E,'Import_FL5_LH_PVTMP_Configs (Do'!Q:Q,"TBD",0,1))} -> G650-14694-05 | AL16: {=if(isblank(E16),"", xlookup(E16,'Import_FL5_LH_PVTMP_Configs (Do'!E:E,'Import_FL5_LH_PVTMP_Configs (Do'!M:M,"TBD",0,1))} -> G710-07670-01 | AM16: {=if(isblank(E16),"", xlookup(E16,'Import_FL5_LH_PVTMP_Configs (Do'!E:E,'Import_FL5_LH_PVTMP_Configs (Do'!N:N,"TBD",0,1))} -> G730-09533-01 | AN16: {=if(isblank(E16),"", xlookup(E16,'Import_FL5_LH_PVTMP_Configs (Do'!E:E,'Import_FL5_LH_PVTMP_Configs (Do'!K:K,"TBD",0,1))} -> G950-15935-00 | AO16: {=if(isblank(E16),"",XLOOKUP(E16,'FL5_G954 Pkg ASSY (Pkg BOM)'!L:L,'FL5_G954 Pkg ASSY (Pkg BOM)'!G:G,"N/A",0,1))} -> G954-08540-00 | AP16: {=if(isblank(E16),"",xlookup(E16,'FL5_G962 Country kit (Accesorie'!L:L,'FL5_G962 Country kit (Accesorie'!G:G,"N/A",0,1))} -> G962-00511-00 | AQ16: {=if(isblank(E16),"", xlookup(E16,'Import_LH_Label approve'!E:E,'Import_LH_Label approve'!M:M,"",0,1))} -> G990-08380-11-01 G990-08380-11-A | AR16: {=if(isblank(E16),"",xlookup(E16,'Import_LH_Label approve'!E:E,'Import_LH_Label approve'!N:N,"",0,1))} -> G990-08491-11-01 G990-08491-11-A | AS16: 128GB | AT16: =if(isblank(E16),"","Yes") -> Yes | AU16: =if(isblank(E16),"",if(mid(E16,9,2)="GB", "Yes","No")) -> No | AV16: =if(isblank(E16),"",if(mid(E16,9,2)="IN", "Yes","No")) -> No | AW16: 6990E | AX16: 840353926400 | AY16: 0840353926400 | AZ16: {=if(isblank(E16),"", xlookup(E16,Import_FL5_LH_PVT_BM!D:D,Import_FL5_LH_PVT_BM!AK:AK,$F$4,0,1))} -> MP | BA16: =if(isblank(E16),"",if(D16="Retail Pack","Retail_10ct",if(D16="Bulk Pack","Bulk_30ct"))) -> Retail_10ct | BB16: {=if(isblank(E16),"",xlookup(F16,z_Others!$B$21:$B$42,z_Others!$G$21:$G$42,"No",0,1))} -> ATT Master Carton Label | BC16: {=if(isblank(E16),"",xlookup(F16,z_Others!$B$21:$B$42,z_Others!$H$21:$H$42,"No",0,1))} -> ATT Pallet Label (BTO) ATT Pallet Label (BTS) | BD16: {=if(isblank(E16),"",xlookup(E16,'Import_VN_Label approve'!E:E,'Import_VN_Label approve'!L:L,"N/A",0,1))} -> G990-08482-11-01 G990-08482-11-A | BE16: {=if(isblank(E16),"",xlookup(E16,'Import_VN_Label approve'!E:E,'Import_VN_Label approve'!N:N,"N/A",0,1))} -> G990-08491-11-01 G990-08491-11-A | BG16: FL5-MP-彩盒包 | BH16: FL5-MP-Colorbox | BI16: 45773 | BJ16: {=if(isblank(E16),"", xlookup(D16,z_Others!$B$5:$B$17,z_Others!$C$5:$C$17,"",0,1))} -> 智能手機 | BK16: 45765 | BL16: {=if(isblank(E16),"",xlookup(E16,'FL5_MP POR_LH_報關備案_G950 & GA'!F:F,'FL5_MP POR_LH_報關備案_G950 & GA'!E:E,"No Need",0,1))} -> Close | BM16: {=if(isblank(E16),"",xlookup($BM$9&E16,'Import_FL5 MPS (06.06.25) - Sor'!E12:E334&'Import_FL5 MPS (06.06.25) - Sor'!F12:F334,'Import_FL5 MPS (06.06.25) - Sor'!ES12:ES334,"No demand",0,1))} -> No demand | BN16: {=if(isblank(E16),"",xlookup($BN$9&E16,'Import_FL5 MPS (06.06.25) - Sor'!E12:E334&'Import_FL5 MPS (06.06.25) - Sor'!F12:F334,'Import_FL5 MPS (06.06.25) - Sor'!ES12:ES334,"No demand",0,1))} -> No demand | BO16: {=if(isblank(E16),"",xlookup($BO$9&E16,'Import_FL5 MPS (06.06.25) - Sor'!E12:E334&'Import_FL5 MPS (06.06.25) - Sor'!F12:F334,'Import_FL5 MPS (06.06.25) - Sor'!ES12:ES334,"No demand",0,1))} -> No demand | BP16: {=if(isblank(E16),"", xlookup(E16,'Import_LH_Label approve'!E:E,'Import_LH_Label approve'!L:L,"",0,1))} | BQ16: {=if(isblank(E16),"",xlookup(E16,'Import_VN_Label approve'!E:E,'Import_VN_Label approve'!M:M,"N/A",0,1))}
B17: 6 | C17: Pristine | D17: Retail Pack | E17: GA10246-US | F17: AT&T, US | G17: UAT | H17: {=xlookup(F17,z_Others!$B$21:$B$45,z_Others!$E$21:$E$45,"",0,1)} -> mmWave | I17: CLR4 | J17: {=if(isblank(E17),"",xlookup(I17,z_Others!$M$17:$M$20,z_Others!$O$17:$O$20,"",0,1))} -> Indigo | K17: {=xlookup(I17,z_Others!$M$17:$M$20,z_Others!$N$17:$N$20,"",0,1)} -> BUE | L17: {=xlookup(F17,z_Others!$B$21:$B$45,z_Others!$D$21:$D$45,"",0,1)} -> GLBW0 | M17: {=xlookup(F17,z_Others!$B$21:$B$45,z_Others!$C$21:$C$45,"",0,1)} -> ATT | N17: {=if(isblank(E17),"",xlookup($N$9&M17,z_Others!$X$5:$X$17&z_Others!$W$5:$W$17,z_Others!$Z$5:$Z$17,"",0,1))} -> 35582324 | O17: {=if(isblank(E17),"",xlookup($N$9&M17,z_Others!$X$5:$X$17&z_Others!$W$5:$W$17,z_Others!$AH$5:$AH$17,"",0,1))} -> 35 582324 020000x | P17: {=if(isblank(E17),"",xlookup($N$9&M17,z_Others!$X$5:$X$17&z_Others!$W$5:$W$17,z_Others!$AI$5:$AI$17,"",0,1))} -> 35 582324 999999x | Q17: 04:00:6E:C4:01:C2 64:9D:38:C7:BC:9E 64:9D:38:DE:9F:FE 64:9D:38:EC:5B:9E B0:D5:FB:A3:48:10 34:39:16:36:EE:80 B0:D5:FB:DD:43:D0 34:39:16:5D:00:FC 30:E0:44:6D:2C:72 | R17: 04:00:6E:C8:95:A1 64:9D:38:CC:50:7D 64:9D:38:E3:33:DD 64:9D:38:F0:EF:7D B0:D5:FB:AA:E9:2F 34:39:16:3C:A3:6F B0:D5:FB:DF:2F:FF 34:39:16:64:A2:1B 30:E0:44:74:CD:91 | S17: {=if(isblank(E17),"",xlookup($S$9&M17,z_Others!$X$5:$X$17&z_Others!$W$5:$W$17,z_Others!$Z$5:$Z$17,"",0,1))} -> 35484520 | T17: {=if(isblank(E17),"",xlookup($S$9&M17,z_Others!$X$5:$X$17&z_Others!$W$5:$W$17,z_Others!$AH$5:$AH$17,"",0,1))} -> 35 484520 020000x | U17: {=if(isblank(E17),"",xlookup($S$9&M17,z_Others!$X$5:$X$17&z_Others!$W$5:$W$17,z_Others!$AI$5:$AI$17,"",0,1))} -> 35 484520 999999x | V17: =if(isblank(E17),"",$V$9) -> 64:9D:38:32:91:82 B0:D5:FB:C6:60:70 | W17: =if(isblank(E17),"",$W$9) -> 64:9D:38:37:25:61 B0:D5:FB:CE:01:8F | X17: =if(isblank(E17),"",$X$9) -> MP1.0 | Z17: =if(isblank(E17),"",$Z$9) -> Android 16 | AA17: =if(isblank(F17),"",$Z$9) -> Android 16 | AB17: SKU, CLR4, GOOD, MMWAVE, AT&T, US, FL5 | AC17: Pixel 10, Indigo, 128GB, AT&T, US | AD17: BD1A.250702.001 | AE17: BD3A.250721.001.E1 | AF17: BD1A.250702.001 | AG17: BD3A.250721.001.E1 | AH17: {=if(isblank(E17),"",xlookup(F17,z_Others!$B$21:$B$45,z_Others!$F$21:$F$45,"TBD",0,1))} -> US | AI17: {=if(isblank(E17),"", xlookup(E17,'Import_FL5_LH_PVTMP_Configs (Do'!E:E,'Import_FL5_LH_PVTMP_Configs (Do'!O:O,"TBD",0,1))} -> G710-07800-01 | AK17: {=if(isblank(E17),"", xlookup(E17,'Import_FL5_LH_PVTMP_Configs (Do'!E:E,'Import_FL5_LH_PVTMP_Configs (Do'!Q:Q,"TBD",0,1))} -> G650-14694-05 | AL17: {=if(isblank(E17),"", xlookup(E17,'Import_FL5_LH_PVTMP_Configs (Do'!E:E,'Import_FL5_LH_PVTMP_Configs (Do'!M:M,"TBD",0,1))} -> G710-07670-01 | AM17: {=if(isblank(E17),"", xlookup(E17,'Import_FL5_LH_PVTMP_Configs (Do'!E:E,'Import_FL5_LH_PVTMP_Configs (Do'!N:N,"TBD",0,1))} -> G730-09533-04 | AN17: {=if(isblank(E17),"", xlookup(E17,'Import_FL5_LH_PVTMP_Configs (Do'!E:E,'Import_FL5_LH_PVTMP_Configs (Do'!K:K,"TBD",0,1))} -> G950-15935-03 | AO17: {=if(isblank(E17),"",XLOOKUP(E17,'FL5_G954 Pkg ASSY (Pkg BOM)'!L:L,'FL5_G954 Pkg ASSY (Pkg BOM)'!G:G,"N/A",0,1))} -> G954-08540-00 | AP17: {=if(isblank(E17),"",xlookup(E17,'FL5_G962 Country kit (Accesorie'!L:L,'FL5_G962 Country kit (Accesorie'!G:G,"N/A",0,1))} -> G962-00511-00 | AQ17: {=if(isblank(E17),"", xlookup(E17,'Import_LH_Label approve'!E:E,'Import_LH_Label approve'!M:M,"",0,1))} -> G990-08380-41-01 G990-08380-41-A | AR17: {=if(isblank(E17),"",xlookup(E17,'Import_LH_Label approve'!E:E,'Import_LH_Label approve'!N:N,"",0,1))} -> G990-08491-41-01 G990-08491-41-A | AS17: 128GB | AT17: =if(isblank(E17),"","Yes") -> Yes | AU17: =if(isblank(E17),"",if(mid(E17,9,2)="GB", "Yes","No")) -> No | AV17: =if(isblank(E17),"",if(mid(E17,9,2)="IN", "Yes","No")) -> No | AW17: 6991E | AX17: 840353926431 | AY17: 0840353926431 | AZ17: {=if(isblank(E17),"", xlookup(E17,Import_FL5_LH_PVT_BM!D:D,Import_FL5_LH_PVT_BM!AK:AK,$F$4,0,1))} -> MP | BA17: =if(isblank(E17),"",if(D17="Retail Pack","Retail_10ct",if(D17="Bulk Pack","Bulk_30ct"))) -> Retail_10ct | BB17: {=if(isblank(E17),"",xlookup(F17,z_Others!$B$21:$B$42,z_Others!$G$21:$G$42,"No",0,1))} -> ATT Master Carton Label | BC17: {=if(isblank(E17),"",xlookup(F17,z_Others!$B$21:$B$42,z_Others!$H$21:$H$42,"No",0,1))} -> ATT Pallet Label (BTO) ATT Pallet Label (BTS) | BD17: {=if(isblank(E17),"",xlookup(E17,'Import_VN_Label approve'!E:E,'Import_VN_Label approve'!L:L,"N/A",0,1))} -> G990-08482-41-01 G990-08482-41-A | BE17: {=if(isblank(E17),"",xlookup(E17,'Import_VN_Label approve'!E:E,'Import_VN_Label approve'!N:N,"N/A",0,1))} -> G990-08491-41-01 G990-08491-41-A | BG17: FL5-MP-彩盒包 | BH17: FL5-MP-Colorbox | BI17: 45773 | BJ17: {=if(isblank(E17),"", xlookup(D17,z_Others!$B$5:$B$17,z_Others!$C$5:$C$17,"",0,1))} -> 智能手機 | BK17: 45782 | BL17: {=if(isblank(E17),"",xlookup(E17,'FL5_MP POR_LH_報關備案_G950 & GA'!F:F,'FL5_MP POR_LH_報關備案_G950 & GA'!E:E,"No Need",0,1))} -> Close | BM17: {=if(isblank(E17),"",xlookup($BM$9&E17,'Import_FL5 MPS (06.06.25) - Sor'!E13:E334&'Import_FL5 MPS (06.06.25) - Sor'!F13:F334,'Import_FL5 MPS (06.06.25) - Sor'!ES13:ES334,"No demand",0,1))} -> No demand | BN17: {=if(isblank(E17),"",xlookup($BN$9&E17,'Import_FL5 MPS (06.06.25) - Sor'!E13:E334&'Import_FL5 MPS (06.06.25) - Sor'!F13:F334,'Import_FL5 MPS (06.06.25) - Sor'!ES13:ES334,"No demand",0,1))} -> No demand | BO17: {=if(isblank(E17),"",xlookup($BO$9&E17,'Import_FL5 MPS (06.06.25) - Sor'!E13:E334&'Import_FL5 MPS (06.06.25) - Sor'!F13:F334,'Import_FL5 MPS (06.06.25) - Sor'!ES13:ES334,"No demand",0,1))} -> No demand | BP17: {=if(isblank(E17),"", xlookup(E17,'Import_LH_Label approve'!E:E,'Import_LH_Label approve'!L:L,"",0,1))} | BQ17: {=if(isblank(E17),"",xlookup(E17,'Import_VN_Label approve'!E:E,'Import_VN_Label approve'!M:M,"N/A",0,1))}
B18: 7 | C18: Pristine | D18: Retail Pack | E18: GA09862-US | F18: TMO, US | G18: UTM | H18: {=xlookup(F18,z_Others!$B$21:$B$45,z_Others!$E$21:$E$45,"",0,1)} -> mmWave | I18: CLR1 | J18: {=if(isblank(E18),"",xlookup(I18,z_Others!$M$17:$M$20,z_Others!$O$17:$O$20,"",0,1))} -> Obsidian | K18: {=xlookup(I18,z_Others!$M$17:$M$20,z_Others!$N$17:$N$20,"",0,1)} -> BLK | L18: {=xlookup(F18,z_Others!$B$21:$B$45,z_Others!$D$21:$D$45,"",0,1)} -> GLBW0 | M18: {=xlookup(F18,z_Others!$B$21:$B$45,z_Others!$C$21:$C$45,"",0,1)} -> TMO | N18: {=if(isblank(E18),"",xlookup($N$9&M18,z_Others!$X$5:$X$17&z_Others!$W$5:$W$17,z_Others!$Z$5:$Z$17,"",0,1))} -> 35163422 | O18: {=if(isblank(E18),"",xlookup($N$9&M18,z_Others!$X$5:$X$17&z_Others!$W$5:$W$17,z_Others!$AH$5:$AH$17,"",0,1))} -> 35 163422 020000x | P18: {=if(isblank(E18),"",xlookup($N$9&M18,z_Others!$X$5:$X$17&z_Others!$W$5:$W$17,z_Others!$AI$5:$AI$17,"",0,1))} -> 35 163422 999999x | Q18: 04:00:6E:C4:01:C2 64:9D:38:C7:BC:9E 64:9D:38:DE:9F:FE 64:9D:38:EC:5B:9E B0:D5:FB:A3:48:10 34:39:16:36:EE:80 B0:D5:FB:DD:43:D0 34:39:16:5D:00:FC 30:E0:44:6D:2C:72 | R18: 04:00:6E:C8:95:A1 64:9D:38:CC:50:7D 64:9D:38:E3:33:DD 64:9D:38:F0:EF:7D B0:D5:FB:AA:E9:2F 34:39:16:3C:A3:6F B0:D5:FB:DF:2F:FF 34:39:16:64:A2:1B 30:E0:44:74:CD:91 | S18: {=if(isblank(E18),"",xlookup($S$9&M18,z_Others!$X$5:$X$17&z_Others!$W$5:$W$17,z_Others!$Z$5:$Z$17,"",0,1))} -> 35676321 | T18: {=if(isblank(E18),"",xlookup($S$9&M18,z_Others!$X$5:$X$17&z_Others!$W$5:$W$17,z_Others!$AH$5:$AH$17,"",0,1))} -> 35 676321 020000x | U18: {=if(isblank(E18),"",xlookup($S$9&M18,z_Others!$X$5:$X$17&z_Others!$W$5:$W$17,z_Others!$AI$5:$AI$17,"",0,1))} -> 35 676321 999999x | V18: =if(isblank(E18),"",$V$9) -> 64:9D:38:32:91:82 B0:D5:FB:C6:60:70 | W18: =if(isblank(E18),"",$W$9) -> 64:9D:38:37:25:61 B0:D5:FB:CE:01:8F | X18: =if(isblank(E18),"",$X$9) -> MP1.0 | Z18: =if(isblank(E18),"",$Z$9) -> Android 16 | AA18: =if(isblank(F18),"",$Z$9) -> Android 16 | AB18: SKU, CLR1, GOOD, MMWAVE, TMO, US, FL5 | AC18: Pixel 10, Obsidian, 128GB, TMO, US | AD18: BD1A.250702.001 | AE18: BD3A.250721.001.E1 | AF18: BD1A.250702.001 | AG18: BD3A.250721.001.E1 | AH18: {=if(isblank(E18),"",xlookup(F18,z_Others!$B$21:$B$45,z_Others!$F$21:$F$45,"TBD",0,1))} -> US | AI18: {=if(isblank(E18),"", xlookup(E18,'Import_FL5_LH_PVTMP_Configs (Do'!E:E,'Import_FL5_LH_PVTMP_Configs (Do'!O:O,"TBD",0,1))} -> G710-07800-01 | AK18: {=if(isblank(E18),"", xlookup(E18,'Import_FL5_LH_PVTMP_Configs (Do'!E:E,'Import_FL5_LH_PVTMP_Configs (Do'!Q:Q,"TBD",0,1))} -> G650-14694-05 | AL18: {=if(isblank(E18),"", xlookup(E18,'Import_FL5_LH_PVTMP_Configs (Do'!E:E,'Import_FL5_LH_PVTMP_Configs (Do'!M:M,"TBD",0,1))} -> G710-07670-01 | AM18: {=if(isblank(E18),"", xlookup(E18,'Import_FL5_LH_PVTMP_Configs (Do'!E:E,'Import_FL5_LH_PVTMP_Configs (Do'!N:N,"TBD",0,1))} -> G730-09533-01 | AN18: {=if(isblank(E18),"", xlookup(E18,'Import_FL5_LH_PVTMP_Configs (Do'!E:E,'Import_FL5_LH_PVTMP_Configs (Do'!K:K,"TBD",0,1))} -> G950-15935-00 | AO18: {=if(isblank(E18),"",XLOOKUP(E18,'FL5_G954 Pkg ASSY (Pkg BOM)'!L:L,'FL5_G954 Pkg ASSY (Pkg BOM)'!G:G,"N/A",0,1))} -> G954-08540-00 | AP18: {=if(isblank(E18),"",xlookup(E18,'FL5_G962 Country kit (Accesorie'!L:L,'FL5_G962 Country kit (Accesorie'!G:G,"N/A",0,1))} -> G962-00511-00 | AQ18: {=if(isblank(E18),"", xlookup(E18,'Import_LH_Label approve'!E:E,'Import_LH_Label approve'!M:M,"",0,1))} -> G990-08380-11-01 G990-08380-11-A | AR18: {=if(isblank(E18),"",xlookup(E18,'Import_LH_Label approve'!E:E,'Import_LH_Label approve'!N:N,"",0,1))} -> G990-08492-11-02 G990-08492-11-A | AS18: 128GB | AT18: =if(isblank(E18),"","Yes") -> Yes | AU18: =if(isblank(E18),"",if(mid(E18,9,2)="GB", "Yes","No")) -> No | AV18: =if(isblank(E18),"",if(mid(E18,9,2)="IN", "Yes","No")) -> No | AW18: 840353926684 | AX18: 840353926684 | AY18: 0840353926684 | AZ18: {=if(isblank(E18),"", xlookup(E18,Import_FL5_LH_PVT_BM!D:D,Import_FL5_LH_PVT_BM!AK:AK,$F$4,0,1))} -> MP | BA18: =if(isblank(E18),"",if(D18="Retail Pack","Retail_10ct",if(D18="Bulk Pack","Bulk_30ct"))) -> Retail_10ct | BB18: {=if(isblank(E18),"",xlookup(F18,z_Others!$B$21:$B$42,z_Others!$G$21:$G$42,"No",0,1))} -> TMO Master Carton Label | BC18: {=if(isblank(E18),"",xlookup(F18,z_Others!$B$21:$B$42,z_Others!$H$21:$H$42,"No",0,1))} -> T-Mobile Pallet Label (BTO) T-Mobile Pallet Label (BTS) | BD18: {=if(isblank(E18),"",xlookup(E18,'Import_VN_Label approve'!E:E,'Import_VN_Label approve'!L:L,"N/A",0,1))} -> G990-08482-11-01 G990-08482-11-A | BE18: {=if(isblank(E18),"",xlookup(E18,'Import_VN_Label approve'!E:E,'Import_VN_Label approve'!N:N,"N/A",0,1))} -> G990-08492-11-02 G990-08492-11-A | BG18: FL5-MP-彩盒包 | BH18: FL5-MP-Colorbox | BI18: 45773 | BJ18: {=if(isblank(E18),"", xlookup(D18,z_Others!$B$5:$B$17,z_Others!$C$5:$C$17,"",0,1))} -> 智能手機 | BK18: 45765 | BL18: {=if(isblank(E18),"",xlookup(E18,'FL5_MP POR_LH_報關備案_G950 & GA'!F:F,'FL5_MP POR_LH_報關備案_G950 & GA'!E:E,"No Need",0,1))} -> Close | BM18: {=if(isblank(E18),"",xlookup($BM$9&E18,'Import_FL5 MPS (06.06.25) - Sor'!E14:E334&'Import_FL5 MPS (06.06.25) - Sor'!F14:F334,'Import_FL5 MPS (06.06.25) - Sor'!ES14:ES334,"No demand",0,1))} -> No demand | BN18: {=if(isblank(E18),"",xlookup($BN$9&E18,'Import_FL5 MPS (06.06.25) - Sor'!E14:E334&'Import_FL5 MPS (06.06.25) - Sor'!F14:F334,'Import_FL5 MPS (06.06.25) - Sor'!ES14:ES334,"No demand",0,1))} -> No demand | BO18: {=if(isblank(E18),"",xlookup($BO$9&E18,'Import_FL5 MPS (06.06.25) - Sor'!E14:E334&'Import_FL5 MPS (06.06.25) - Sor'!F14:F334,'Import_FL5 MPS (06.06.25) - Sor'!ES14:ES334,"No demand",0,1))} -> No demand | BP18: {=if(isblank(E18),"", xlookup(E18,'Import_LH_Label approve'!E:E,'Import_LH_Label approve'!L:L,"",0,1))} | BQ18: {=if(isblank(E18),"",xlookup(E18,'Import_VN_Label approve'!E:E,'Import_VN_Label approve'!M:M,"N/A",0,1))}
B19: 8 | C19: Pristine | D19: Retail Pack | E19: GA10252-US | F19: TMO, US | G19: UTM | H19: {=xlookup(F19,z_Others!$B$21:$B$45,z_Others!$E$21:$E$45,"",0,1)} -> mmWave | I19: CLR4 | J19: {=if(isblank(E19),"",xlookup(I19,z_Others!$M$17:$M$20,z_Others!$O$17:$O$20,"",0,1))} -> Indigo | K19: {=xlookup(I19,z_Others!$M$17:$M$20,z_Others!$N$17:$N$20,"",0,1)} -> BUE | L19: {=xlookup(F19,z_Others!$B$21:$B$45,z_Others!$D$21:$D$45,"",0,1)} -> GLBW0 | M19: {=xlookup(F19,z_Others!$B$21:$B$45,z_Others!$C$21:$C$45,"",0,1)} -> TMO | N19: {=if(isblank(E19),"",xlookup($N$9&M19,z_Others!$X$5:$X$17&z_Others!$W$5:$W$17,z_Others!$Z$5:$Z$17,"",0,1))} -> 35163422 | O19: {=if(isblank(E19),"",xlookup($N$9&M19,z_Others!$X$5:$X$17&z_Others!$W$5:$W$17,z_Others!$AH$5:$AH$17,"",0,1))} -> 35 163422 020000x | P19: {=if(isblank(E19),"",xlookup($N$9&M19,z_Others!$X$5:$X$17&z_Others!$W$5:$W$17,z_Others!$AI$5:$AI$17,"",0,1))} -> 35 163422 999999x | Q19: 04:00:6E:C4:01:C2 64:9D:38:C7:BC:9E 64:9D:38:DE:9F:FE 64:9D:38:EC:5B:9E B0:D5:FB:A3:48:10 34:39:16:36:EE:80 B0:D5:FB:DD:43:D0 34:39:16:5D:00:FC 30:E0:44:6D:2C:72 | R19: 04:00:6E:C8:95:A1 64:9D:38:CC:50:7D 64:9D:38:E3:33:DD 64:9D:38:F0:EF:7D B0:D5:FB:AA:E9:2F 34:39:16:3C:A3:6F B0:D5:FB:DF:2F:FF 34:39:16:64:A2:1B 30:E0:44:74:CD:91 | S19: {=if(isblank(E19),"",xlookup($S$9&M19,z_Others!$X$5:$X$17&z_Others!$W$5:$W$17,z_Others!$Z$5:$Z$17,"",0,1))} -> 35676321 | T19: {=if(isblank(E19),"",xlookup($S$9&M19,z_Others!$X$5:$X$17&z_Others!$W$5:$W$17,z_Others!$AH$5:$AH$17,"",0,1))} -> 35 676321 020000x | U19: {=if(isblank(E19),"",xlookup($S$9&M19,z_Others!$X$5:$X$17&z_Others!$W$5:$W$17,z_Others!$AI$5:$AI$17,"",0,1))} -> 35 676321 999999x | V19: =if(isblank(E19),"",$V$9) -> 64:9D:38:32:91:82 B0:D5:FB:C6:60:70 | W19: =if(isblank(E19),"",$W$9) -> 64:9D:38:37:25:61 B0:D5:FB:CE:01:8F | X19: =if(isblank(E19),"",$X$9) -> MP1.0 | Z19: =if(isblank(E19),"",$Z$9) -> Android 16 | AA19: =if(isblank(F19),"",$Z$9) -> Android 16 | AB19: SKU, CLR4, GOOD, MMWAVE, Tmobile, US, FL5 | AC19: Pixel 10, Indigo, 128GB, TMO, US | AD19: BD1A.250702.001 | AE19: BD3A.250721.001.E1 | AF19: BD1A.250702.001 | AG19: BD3A.250721.001.E1 | AH19: {=if(isblank(E19),"",xlookup(F19,z_Others!$B$21:$B$45,z_Others!$F$21:$F$45,"TBD",0,1))} -> US | AI19: {=if(isblank(E19),"", xlookup(E19,'Import_FL5_LH_PVTMP_Configs (Do'!E:E,'Import_FL5_LH_PVTMP_Configs (Do'!O:O,"TBD",0,1))} -> G710-07800-01 | AK19: {=if(isblank(E19),"", xlookup(E19,'Import_FL5_LH_PVTMP_Configs (Do'!E:E,'Import_FL5_LH_PVTMP_Configs (Do'!Q:Q,"TBD",0,1))} -> G650-14694-05 | AL19: {=if(isblank(E19),"", xlookup(E19,'Import_FL5_LH_PVTMP_Configs (Do'!E:E,'Import_FL5_LH_PVTMP_Configs (Do'!M:M,"TBD",0,1))} -> G710-07670-01 | AM19: {=if(isblank(E19),"", xlookup(E19,'Import_FL5_LH_PVTMP_Configs (Do'!E:E,'Import_FL5_LH_PVTMP_Configs (Do'!N:N,"TBD",0,1))} -> G730-09533-04 | AN19: {=if(isblank(E19),"", xlookup(E19,'Import_FL5_LH_PVTMP_Configs (Do'!E:E,'Import_FL5_LH_PVTMP_Configs (Do'!K:K,"TBD",0,1))} -> G950-15935-03 | AO19: {=if(isblank(E19),"",XLOOKUP(E19,'FL5_G954 Pkg ASSY (Pkg BOM)'!L:L,'FL5_G954 Pkg ASSY (Pkg BOM)'!G:G,"N/A",0,1))} -> G954-08540-00 | AP19: {=if(isblank(E19),"",xlookup(E19,'FL5_G962 Country kit (Accesorie'!L:L,'FL5_G962 Country kit (Accesorie'!G:G,"N/A",0,1))} -> G962-00511-00 | AQ19: {=if(isblank(E19),"", xlookup(E19,'Import_LH_Label approve'!E:E,'Import_LH_Label approve'!M:M,"",0,1))} -> G990-08380-41-01 G990-08380-41-A | AR19: {=if(isblank(E19),"",xlookup(E19,'Import_LH_Label approve'!E:E,'Import_LH_Label approve'!N:N,"",0,1))} -> G990-08492-41-02 G990-08492-41-A | AS19: 128GB | AT19: =if(isblank(E19),"","Yes") -> Yes | AU19: =if(isblank(E19),"",if(mid(E19,9,2)="GB", "Yes","No")) -> No | AV19: =if(isblank(E19),"",if(mid(E19,9,2)="IN", "Yes","No")) -> No | AW19: 840353926691 | AX19: 840353926691 | AY19: 0840353926691 | AZ19: {=if(isblank(E19),"", xlookup(E19,Import_FL5_LH_PVT_BM!D:D,Import_FL5_LH_PVT_BM!AK:AK,$F$4,0,1))} -> MP | BA19: =if(isblank(E19),"",if(D19="Retail Pack","Retail_10ct",if(D19="Bulk Pack","Bulk_30ct"))) -> Retail_10ct | BB19: {=if(isblank(E19),"",xlookup(F19,z_Others!$B$21:$B$42,z_Others!$G$21:$G$42,"No",0,1))} -> TMO Master Carton Label | BC19: {=if(isblank(E19),"",xlookup(F19,z_Others!$B$21:$B$42,z_Others!$H$21:$H$42,"No",0,1))} -> T-Mobile Pallet Label (BTO) T-Mobile Pallet Label (BTS) | BD19: {=if(isblank(E19),"",xlookup(E19,'Import_VN_Label approve'!E:E,'Import_VN_Label approve'!L:L,"N/A",0,1))} -> G990-08482-41-01 G990-08482-41-A | BE19: {=if(isblank(E19),"",xlookup(E19,'Import_VN_Label approve'!E:E,'Import_VN_Label approve'!N:N,"N/A",0,1))} -> G990-08492-41-02 G990-08492-41-A | BG19: FL5-MP-彩盒包 | BH19: FL5-MP-Colorbox | BI19: 45773 | BJ19: {=if(isblank(E19),"", xlookup(D19,z_Others!$B$5:$B$17,z_Others!$C$5:$C$17,"",0,1))} -> 智能手機 | BK19: 45782 | BL19: {=if(isblank(E19),"",xlookup(E19,'FL5_MP POR_LH_報關備案_G950 & GA'!F:F,'FL5_MP POR_LH_報關備案_G950 & GA'!E:E,"No Need",0,1))} -> Close | BM19: {=if(isblank(E19),"",xlookup($BM$9&E19,'Import_FL5 MPS (06.06.25) - Sor'!E15:E334&'Import_FL5 MPS (06.06.25) - Sor'!F15:F334,'Import_FL5 MPS (06.06.25) - Sor'!ES15:ES334,"No demand",0,1))} -> No demand | BN19: {=if(isblank(E19),"",xlookup($BN$9&E19,'Import_FL5 MPS (06.06.25) - Sor'!E15:E334&'Import_FL5 MPS (06.06.25) - Sor'!F15:F334,'Import_FL5 MPS (06.06.25) - Sor'!ES15:ES334,"No demand",0,1))} -> No demand | BO19: {=if(isblank(E19),"",xlookup($BO$9&E19,'Import_FL5 MPS (06.06.25) - Sor'!E15:E334&'Import_FL5 MPS (06.06.25) - Sor'!F15:F334,'Import_FL5 MPS (06.06.25) - Sor'!ES15:ES334,"No demand",0,1))} -> No demand | BP19: {=if(isblank(E19),"", xlookup(E19,'Import_LH_Label approve'!E:E,'Import_LH_Label approve'!L:L,"",0,1))} | BQ19: {=if(isblank(E19),"",xlookup(E19,'Import_VN_Label approve'!E:E,'Import_VN_Label approve'!M:M,"N/A",0,1))}
