Workbook

Sheet BZ5 MP Release Note
A1: Lesson learn: | B1: 所有新增的SKU都需要EPM放到label approval tracking list內, label PE維護模板並ping客戶取到approval後才能生產 | D1: BZ5 VN MP Retail/Carton/Pallet Labels Approval Tracking List | E1: [Int]BZ5 PVT/MP config list | F1: BZ5 SKU Matrix (go/bz5-sku-matrix)
A3: Version | B3: Date | C3: Change Description | D3: Editor
A4: V1 | C4: First version, on-going | D4: Gina周曉萍
A5: V2 | B5: 45819 | C5: Update the AA column SKU desription, cancelled GA10296-US this TMO Pristine SKU | D5: Gina周曉萍
A6: V3 | B6: 45821 | C6: EC released EU SKU need to update the retail label AU Column to REV B, remark in yellow color | D6: Gina周曉萍
A7: V4 | B7: 45821 | C7: Update the AU column - change the SKU RAP label template for the GB SKU to REV B and mark the yellow parts. | D7: Gina周曉萍
A8: V5 | B8: 45848 | C8: FRC Zombie for Non-VZW Sku :BD1A.250702.001 FRC SW for All SKUs: BD1A.250702.001 | D8: Maevy
A9: V6 | B9: 45859 | C9: FRC SW for VZW SKUs: BD1A.250702.001.A3 FRC Zombie for Non VZW SKUs: BD1A.250702.001 | D9: Maevy
A10: V6 | B10: 45861 | C10: New tac range: ** BZ5 ** B0:D5:FB:BE:BF:50 - B0:D5:FB:C6:60:6F Qty: 500K | D10: Maevy
A11: V7 | B11: 45883 | C11: Change "Retail RAP printing GPN REV A" for IN/JP SKUs | D11: Maevy
A12: V8 | B12: 45899 | C12: Change BOB AW GPN from rev B to rev C (for CA SKUs) | D12: Maevy
A13: V9 | B13: 45915 | C13: Change BOB AW GPN (for US SKUs) | D13: Maevy
A14: V10 | B14: 45930 | C14: a new IMEI range for BZ5 NA in VN Range: 35 718913 340000x - 35 718913 639999x new MAC address range for BZ5 in VN Range: 30:E0:44:48:18:42 - 30:E0:44:4F:B9:61

Sheet BZ5 MP Control table_ VN
A1: DRI: Gina (EPM); Suataining OPM | K1: TTL BOM config QTY: | M1: 129 | N1: This table excluded Demo SKU, VN will not produce demo SKU
C2: Update Date: | D2: 45794 | E2: (V6) | J2: Cat. | K2: Config Q'ty | L2: Cat. | M2: Config Q'ty
J3: Pristine | K3: 55 | L3: IQ | M3: =COUNTIF($C$9:$C$300,L3) -> 14
J4: Press | K4: =COUNTIF($C$9:$C$300,J4) -> 16 | L4: CLNR | M4: =COUNTIF($C$9:$C$300,L4) -> 44
J5: Demo | K5: =COUNTIF($C$9:$C$300,J5) -> 0 | L5: Special build
A7: Item | B7: Stage | C7: Purpose | D7: Packout Type （包裝類型） | E7: GB PN (裸機料號) | F7: Laser GBPN (鐳雕裸機料號) | G7: Sales SKU （包裝料號） | H7: SKU Name | I7: MLB GPN 主板料號 | J7: RF Type 基頻種類 | K7: Color key | L7: Color ID (SFC/iFUSE) | M7: Color Name in sleeve | N7: WCC [WiFi Country Code] | O7: Model# 產品型號# | P7: P-SKU | Q7: SKU ID (C-SKU for ATT only) | R7: UPC Code-12 (except EMEA) | S7: EAN Code-13 (EMEA only) | T7: UFS | U7: TAC Code 出貨地 | V7: TAC Start | W7: TAC(IMEI) Start Range | X7: TAC(IMEI) End Range | Y7: WiFi/BT Start Range | Z7: WiFi/BT End Range | AA7: Description (描述,關務備案內容) | AB7: eSIM | AC7: Regulatory /EU laser | AD7: IN COO Laser | AE7: SIMTray Laser | AF7: Unite/Carton 包規 | AG7: Sleeve 袖套 以BOM为准 | AH7: Closure Label 封口貼紙 以BOM为准 | AI7: DOC bundle 以BOM为准 | AJ7: C2C Cable 以BOM为准 | AK7: Device Wrap 以BOM为准 | AL7: IN MRP標籤 | AM7: DEMO LABEL | AN7: LOT X REWORK LABEL 能效标签 | AO7: SFC Routing SFC 路由名稱 | AP7: SW version | AQ7: Zombie OTA SW ROM | AR7: HW Ver. 硬體版本 | AS7: Android Ver. 安卓版本 以手機SW版本附帶為準 | AT7: BOB printing GPN REV C | AU7: Retail RAP printing GPN REV A | AV7: IN MRP printing GPN | AW7: IN MRP Price | AX7: Master Carton Label GPN & Rev for printing | AY7: Pallet Label GPN & Rev for printing | AZ7: Overlabel for Zombie use | BA7: Overlabel artwork
A8: example | B8: PVT/MP | C8: Pristine | D8: 彩盒包 | E8: G950-13298-01 | G8: GA05158-US | H8: VZW, US | I8: G710-05689-00 | J8: mmWave | K8: CLR1 | L8: BLK | M8: Obsidian | N8: US | O8: GR83Y | P8: UVZ | R8: 840353905801 | T8: 128 GB | U8: VZW | V8: 35082327 | W8: 35 082327 020000x 35 082327 520000x 35 082327 570000x 35 082327 670000x 35 082327 770000x | X8: 35 082327 519999x 35 082327 569999x 35 082327 669999x 35 082327 769999x 35 082327 869999x | Y8: 20:F0:94:01:64:0A E8:D5:2B:5D:CE:B2 08:8B:C8:4C:61:C6 C0:1C:6A:A6:88:28 FC:41:16:B0:25:BA 98:98:FB:0E:97:26 98:98:FB:22:6D:46 04:00:6E:87:DB:52 04:00:6E:AE:4F:12 | Z8: 20:F0:94:08:3A:D3 E8:D5:2B:5E:99:07 08:8B:C8:54:02:E5 C0:1C:6A:AE:29:47 FC:41:16:B7:C6:D9 98:98:FB:13:2B:05 98:98:FB:27:01:25 04:00:6E:8C:6F:31 04:00:6E:B2:E2:F1 | AA8: Pixel 9 Pro, Obsidian, 128GB, VZW, US | AB8: Yes | AC8: NO | AD8: NO | AE8: NO | AF8: 10ct | AG8: Yes | AH8: Yes | AI8: Yes | AJ8: Yes | AK8: Yes | AL8: NO | AO8: CM4-MP-彩盒包nomal | AP8: BP1A.250405.007.D1 | AR8: MP1.0 | AZ8: zombie 時使用
A9: 1 | B9: {=IFERROR( INDEX('POR Config List'!A:A,MATCH(G9,'POR Config List'!D:D,0)),"")} -> PVT/MP | C9: {=IFERROR(INDEX('label approval artwork'!E:E,MATCH(G9,'label approval artwork'!F:F,0),""),"")} -> Pristine | D9: =IF(ISBLANK(C9) ,"",IF(C9="CLNR","builk pack","retail pack")) -> retail pack | E9: {=IF(ISBLANK(G9),"",INDEX('POR Config List'!K:K,MATCH(G9,'POR Config List'!D:D,0)))} -> G950-15986-01 | F9: {=IF(ISBLANK(G9),"",INDEX('POR Config List'!J:J,MATCH(G9,'POR Config List'!D:D,0)))} | G9: GA09187-US | H9: {=IF(ISBLANK(G9),"",INDEX('MP SKUs'!G:G,MATCH(G9,'MP SKUs'!A:A,0)))} -> US-VZW | I9: {=IF(ISBLANK(G9),"",INDEX('POR Config List'!O:O,MATCH(G9,'POR Config List'!D:D,0)))} -> G710-07813-00 | J9: {=IF(ISBLANK(G9),"",INDEX('POR Config List'!H:H,MATCH(G9,'POR Config List'!D:D,0)))} -> mmWave | K9: {=IF(ISBLANK(G9),"",INDEX('POR Config List'!G:G,MATCH(G9,'POR Config List'!D:D,0)))} -> CLR1 | L9: =IF(ISBLANK(K9),"", IF(K9="CLR1","BLK",IF(K9="CLR2","WHT",IF(K9="CLR3","GRY",IF(K9="CLR4","GRN"))))) -> BLK | M9: {=IF(ISBLANK(G9),"",INDEX('label approval artwork'!Q:Q,MATCH( G9,'label approval artwork'!F:F,0)))} -> Obsidian | N9: US | O9: {=IF(ISBLANK(G9),"",INDEX('POR Config List'!C:C,MATCH(G9,'POR Config List'!D:D,0)))} -> G4QUR | P9: =IF(ISBLANK(G9),"",IF(H9="US GStore","UGS",IF(H9="US-VZW","UVZ",IF(H9="US - AT&T","UAT",IF(H9="US - Tmobile","UTM",IF(H9="JP","AJP",IF(H9="IN","NCA",IF(H9="CA/TW/SG/AU/MY/MX","NCA",IF(H9="EU(GB, DE, IT, ES, IE, FR, NL, BE, AT, CH, PT, PL, CEE (RO, CZ, HU, SI, LV, LT, EE, FI), NO,SE,DK, SK)","EMA"))))))))) -> UVZ | Q9: {=IF(ISBLANK(G9),"",INDEX('label approval artwork'!J:J,MATCH( G9,'label approval artwork'!F:F,0)))} | R9: {=IFERROR( IF(P9<>"EMA",INDEX('label approval artwork'!H:H,MATCH(G9,'label approval artwork'!F:F,0),"")),"")} -> 840353926042 | T9: {=IF(ISBLANK(G9),"",INDEX('POR Config List'!I:I,MATCH(G9,'POR Config List'!D:D,0)))} -> 128GB | U9: {=INDEX('MP SKUs'!L:L,MATCH(G9,'MP SKUs'!A:A,0))} -> VZW | V9: =LEFT(W9,9) -> 35 531042 | W9: 35 531042 020000 35 531042 320000x | X9: 35 531042 319999 35 531042 619999x | Y9: 04:00:6E:C8:EB:92 64:9D:38:00:00:32 B0:D5:FB:BE:BF:50 30:E0:44:48:18:42 | Z9: 04:00:6E:CA:FE:D1 64:9D:38:02:80:D1 B0:D5:FB:C6:60:6F 30:E0:44:4F:B9:61 | AA9: {=INDEX('POR Config List'!F:F,MATCH(G9,'POR Config List'!D:D,0))} -> Pixel 10 Pro, Obsidian, 128GB, VZW, US | AB9: Yes | AC9: =IF(P9="EMA","Yes","NO") -> NO | AD9: =IF(H9="IN","Yes","NO") -> NO | AE9: =IF(J9="mmwave","NO","Yes") -> NO | AF9: =IF(D9="retail pack","10ct","30ct") -> 10ct | AG9: =IF(D9="retail pack","Yes","NO") -> Yes | AH9: =IF(D9="retail pack","Yes","NO") -> Yes | AI9: =IF(D9="retail pack","Yes","NO") -> Yes | AJ9: =IF(D9="retail pack","Yes","NO") -> Yes | AK9: =IF(D9="retail pack","Yes","NO") -> Yes | AL9: =IF(H9="IN","Yes","NO") -> NO | AM9: =IF(C9="Demo","Yes","NO") -> NO | AN9: =IF(P9="EMA","Yes","NO") -> NO | AO9: BZ5-MP-Colorbox | AP9: BD3A.250721.001.E1 | AR9: MP1.0 | AS9: Android 16 | AT9: G990-08499-11-B | AU9: {=INDEX('label approval artwork'!B:B,MATCH(G9,'label approval artwork'!F:F,0))} -> G990-08505-11-A | AV9: {=IFERROR( INDEX('label approval artwork'!N$1:N$199,MATCH(G9,'label approval artwork'!F$1:F$199,0)),"")} | AX9: VZN Master Carton Label | AY9: VZN Pallet Label -> BTS(Normal case) | AZ9: G952-05413-003AB
A10: 2 | B10: PVT/MP | C10: Pristine | D10: retail pack | E10: G950-15986-03 | G10: GA10276-US | H10: US-VZW | I10: G710-07813-00 | J10: mmWave | K10: CLR3 | L10: GRY | M10: Moonstone | N10: US | O10: G4QUR | P10: UVZ | R10: 840353926066 | T10: 128GB | U10: VZW | V10: 35 531042 | W10: 35 531042 020000 35 531042 320000x | X10: 35 531042 319999 35 531042 619999x | Y10: 04:00:6E:C8:EB:92 64:9D:38:00:00:32 B0:D5:FB:BE:BF:50 30:E0:44:48:18:42 | Z10: 04:00:6E:CA:FE:D1 64:9D:38:02:80:D1 B0:D5:FB:C6:60:6F 30:E0:44:4F:B9:61 | AA10: Pixel 10 Pro, Moonstone, 128GB, VZW, US | AB10: Yes | AC10: NO | AD10: NO | AE10: NO | AF10: 10ct | AG10: Yes | AH10: Yes | AI10: Yes | AJ10: Yes | AK10: Yes | AL10: NO | AM10: NO | AN10: NO | AO10: BZ5-MP-Colorbox | AP10: BD3A.250721.001.E1 | AR10: MP1.0 | AS10: Android 16 | AT10: G990-08499-31-B | AU10: {=INDEX('label approval artwork'!B:B,MATCH(G10,'label approval artwork'!F:F,0))} -> G990-08505-11-A | AX10: VZN Master Carton Label | AY10: VZN Pallet Label -> BTS(Normal case) | AZ10: G952-05413-003AB
A11: 3 | B11: PVT/MP | C11: Pristine | D11: retail pack | E11: G950-18289-01 | G11: GA09896-US | H11: US-VZW | I11: G710-07813-10 | J11: mmWave | K11: CLR1 | L11: BLK | M11: Obsidian | N11: US | O11: G4QUR | P11: UVZ | R11: 840353925328 | T11: 256GB | U11: VZW | V11: 35 531042 | W11: 35 531042 020000 35 531042 320000x | X11: 35 531042 319999 35 531042 619999x | Y11: 04:00:6E:C8:EB:92 64:9D:38:00:00:32 B0:D5:FB:BE:BF:50 30:E0:44:48:18:42 | Z11: 04:00:6E:CA:FE:D1 64:9D:38:02:80:D1 B0:D5:FB:C6:60:6F 30:E0:44:4F:B9:61 | AA11: Pixel 10 Pro, Obsidian, 256GB, VZW, US | AB11: Yes | AC11: NO | AD11: NO | AE11: NO | AF11: 10ct | AG11: Yes | AH11: Yes | AI11: Yes | AJ11: Yes | AK11: Yes | AL11: NO | AM11: NO | AN11: NO | AO11: BZ5-MP-Colorbox | AP11: BD3A.250721.001.E1 | AR11: MP1.0 | AS11: Android 16 | AT11: G990-08499-12-B | AU11: {=INDEX('label approval artwork'!B:B,MATCH(G11,'label approval artwork'!F:F,0))} -> G990-08505-11-A | AX11: VZN Master Carton Label | AY11: VZN Pallet Label -> BTS(Normal case) | AZ11: G952-05413-003AB
A12: 4 | B12: MP | C12: Pristine | D12: retail pack | E12: G950-18289-03 | G12: GA10278-US | H12: US-VZW | I12: G710-07813-10 | J12: mmWave | K12: CLR3 | L12: GRY | M12: Moonstone | N12: US | O12: G4QUR | P12: UVZ | R12: 840353925335 | T12: 256GB | U12: VZW | V12: 35 531042 | W12: 35 531042 020000 35 531042 320000x | X12: 35 531042 319999 35 531042 619999x | Y12: 04:00:6E:C8:EB:92 64:9D:38:00:00:32 B0:D5:FB:BE:BF:50 30:E0:44:48:18:42 | Z12: 04:00:6E:CA:FE:D1 64:9D:38:02:80:D1 B0:D5:FB:C6:60:6F 30:E0:44:4F:B9:61 | AA12: Pixel 10 Pro, Moonstone, 256GB, VZW, US | AB12: Yes | AC12: NO | AD12: NO | AE12: NO | AF12: 10ct | AG12: Yes | AH12: Yes | AI12: Yes | AJ12: Yes | AK12: Yes | AL12: NO | AM12: NO | AN12: NO | AO12: BZ5-MP-Colorbox | AP12: BD3A.250721.001.E1 | AR12: MP1.0 | AS12: Android 16 | AT12: G990-08499-32-B | AU12: {=INDEX('label approval artwork'!B:B,MATCH(G12,'label approval artwork'!F:F,0))} -> G990-08505-11-A | AX12: VZN Master Carton Label | AY12: VZN Pallet Label -> BTS(Normal case) | AZ12: G952-05413-003AB
A13: 5 | B13: PVT/MP | C13: Pristine | D13: retail pack | E13: G950-18291-01 | G13: GA09905-US | H13: US-VZW | I13: G710-07813-20 | J13: mmWave | K13: CLR1 | L13: BLK | M13: Obsidian | N13: US | O13: G4QUR | P13: UVZ | R13: 840353925700 | T13: 512GB | U13: VZW | V13: 35 531042 | W13: 35 531042 020000 35 531042 320000x | X13: 35 531042 319999 35 531042 619999x | Y13: 04:00:6E:C8:EB:92 64:9D:38:00:00:32 B0:D5:FB:BE:BF:50 30:E0:44:48:18:42 | Z13: 04:00:6E:CA:FE:D1 64:9D:38:02:80:D1 B0:D5:FB:C6:60:6F 30:E0:44:4F:B9:61 | AA13: Pixel 10 Pro, Obsidian, 512GB, VZW, US | AB13: Yes | AC13: NO | AD13: NO | AE13: NO | AF13: 10ct | AG13: Yes | AH13: Yes | AI13: Yes | AJ13: Yes | AK13: Yes | AL13: NO | AM13: NO | AN13: NO | AO13: BZ5-MP-Colorbox | AP13: BD3A.250721.001.E1 | AR13: MP1.0 | AS13: Android 16 | AT13: G990-08499-13-B | AU13: {=INDEX('label approval artwork'!B:B,MATCH(G13,'label approval artwork'!F:F,0))} -> G990-08505-11-A | AX13: VZN Master Carton Label | AY13: VZN Pallet Label -> BTS(Normal case) | AZ13: G952-05413-003AB
A14: 6 | B14: MP | C14: Pristine | D14: retail pack | E14: G950-18291-03 | G14: GA10281-US | H14: US-VZW | I14: G710-07813-20 | J14: mmWave | K14: CLR3 | L14: GRY | M14: Moonstone | N14: US | O14: G4QUR | P14: UVZ | R14: 840353925724 | T14: 512GB | U14: VZW | V14: 35 531042 | W14: 35 531042 020000 35 531042 320000x | X14: 35 531042 319999 35 531042 619999x | Y14: 04:00:6E:C8:EB:92 64:9D:38:00:00:32 B0:D5:FB:BE:BF:50 30:E0:44:48:18:42 | Z14: 04:00:6E:CA:FE:D1 64:9D:38:02:80:D1 B0:D5:FB:C6:60:6F 30:E0:44:4F:B9:61 | AA14: Pixel 10 Pro, Moonstone, 512GB, VZW, US | AB14: Yes | AC14: NO | AD14: NO | AE14: NO | AF14: 10ct | AG14: Yes | AH14: Yes | AI14: Yes | AJ14: Yes | AK14: Yes | AL14: NO | AM14: NO | AN14: NO | AO14: BZ5-MP-Colorbox | AP14: BD3A.250721.001.E1 | AR14: MP1.0 | AS14: Android 16 | AT14: G990-08499-33-B | AU14: {=INDEX('label approval artwork'!B:B,MATCH(G14,'label approval artwork'!F:F,0))} -> G990-08505-11-A | AX14: VZN Master Carton Label | AY14: VZN Pallet Label -> BTS(Normal case) | AZ14: G952-05413-003AB
A15: 7 | B15: PVT/MP | C15: Pristine | D15: retail pack | E15: G950-18289-04 | G15: GA10279-US | H15: US-VZW | I15: G710-07813-10 | J15: mmWave | K15: CLR4 | L15: GRN | M15: Jade | N15: US | O15: G4QUR | P15: UVZ | R15: 840353925342 | T15: 256GB | U15: VZW | V15: 35 531042 | W15: 35 531042 020000 35 531042 320000x | X15: 35 531042 319999 35 531042 619999x | Y15: 04:00:6E:C8:EB:92 64:9D:38:00:00:32 B0:D5:FB:BE:BF:50 30:E0:44:48:18:42 | Z15: 04:00:6E:CA:FE:D1 64:9D:38:02:80:D1 B0:D5:FB:C6:60:6F 30:E0:44:4F:B9:61 | AA15: Pixel 10 Pro, Jade, 256GB, VZW, US | AB15: Yes | AC15: NO | AD15: NO | AE15: NO | AF15: 10ct | AG15: Yes | AH15: Yes | AI15: Yes | AJ15: Yes | AK15: Yes | AL15: NO | AM15: NO | AN15: NO | AO15: BZ5-MP-Colorbox | AP15: BD3A.250721.001.E1 | AR15: MP1.0 | AS15: Android 16 | AT15: G990-08499-42-B | AU15: {=INDEX('label approval artwork'!B:B,MATCH(G15,'label approval artwork'!F:F,0))} -> G990-08505-11-A | AX15: VZN Master Carton Label | AY15: VZN Pallet Label -> BTS(Normal case) | AZ15: G952-05413-003AB
A16: 8 | B16: PVT/MP | C16: Pristine | D16: retail pack | E16: G950-15986-01 | G16: GA09885-US | H16: US - AT&T | I16: G710-07813-00 | J16: mmWave | K16: CLR1 | L16: BLK | M16: Obsidian | N16: US | O16: G4QUR | P16: UAT | Q16: 6993E | R16: 840353925069 | T16: 128GB | U16: ATT | V16: 35 980215 | W16: 35 980215 020000 | X16: 35 980215 319999 | Y16: 04:00:6E:C8:EB:92 64:9D:38:00:00:32 B0:D5:FB:BE:BF:50 30:E0:44:48:18:42 | Z16: 04:00:6E:CA:FE:D1 64:9D:38:02:80:D1 B0:D5:FB:C6:60:6F 30:E0:44:4F:B9:61 | AA16: Pixel 10 Pro, Obsidian, 128GB, AT&T, US | AB16: Yes | AC16: NO | AD16: NO | AE16: NO | AF16: 10ct | AG16: Yes | AH16: Yes | AI16: Yes | AJ16: Yes | AK16: Yes | AL16: NO | AM16: NO | AN16: NO | AO16: BZ5-MP-Colorbox | AP16: BD3A.250721.001.E1 | AR16: MP1.0 | AS16: Android 16 | AT16: G990-08499-11-B | AU16: {=INDEX('label approval artwork'!B:B,MATCH(G16,'label approval artwork'!F:F,0))} -> G990-08504-11-A | AX16: MasterCartonLabel_IMEI-EID_ATT_FIH | AY16: ATT Pallet label -> BTS(Normal case) ATT Pallet Label -> BTO(EDI) | AZ16: G952-05413-003AB
A17: 9 | B17: PVT/MP | C17: Pristine | D17: retail pack | E17: G950-15986-03 | G17: GA10285-US | H17: US - AT&T | I17: G710-07813-00 | J17: mmWave | K17: CLR3 | L17: GRY | M17: Moonstone | N17: US | O17: G4QUR | P17: UAT | Q17: 6992E | R17: 840353925083 | T17: 128GB | U17: ATT | V17: 35 980215 | W17: 35 980215 020000 | X17: 35 980215 319999 | Y17: 04:00:6E:C8:EB:92 64:9D:38:00:00:32 B0:D5:FB:BE:BF:50 30:E0:44:48:18:42 | Z17: 04:00:6E:CA:FE:D1 64:9D:38:02:80:D1 B0:D5:FB:C6:60:6F 30:E0:44:4F:B9:61 | AA17: Pixel 10 Pro, Moonstone, 128GB, AT&T, US | AB17: Yes | AC17: NO | AD17: NO | AE17: NO | AF17: 10ct | AG17: Yes | AH17: Yes | AI17: Yes | AJ17: Yes | AK17: Yes | AL17: NO | AM17: NO | AN17: NO | AO17: BZ5-MP-Colorbox | AP17: BD3A.250721.001.E1 | AR17: MP1.0 | AS17: Android 16 | AT17: G990-08499-31-B | AU17: {=INDEX('label approval artwork'!B:B,MATCH(G17,'label approval artwork'!F:F,0))} -> G990-08504-31-A | AX17: MasterCartonLabel_IMEI-EID_ATT_FIH | AY17: ATT Pallet label -> BTS(Normal case) ATT Pallet Label -> BTO(EDI) | AZ17: G952-05413-003AB
A18: 10 | B18: MP | C18: Pristine | D18: retail pack | E18: G950-18289-03 | G18: GA10287-US | H18: US - AT&T | I18: G710-07813-10 | J18: mmWave | K18: CLR3 | L18: GRY | M18: Moonstone | N18: US | O18: G4QUR | P18: UAT | Q18: 6994E | R18: 840353925151 | T18: 256GB | U18: ATT | V18: 35 980215 | W18: 35 980215 020000 | X18: 35 980215 319999 | Y18: 04:00:6E:C8:EB:92 64:9D:38:00:00:32 B0:D5:FB:BE:BF:50 30:E0:44:48:18:42 | Z18: 04:00:6E:CA:FE:D1 64:9D:38:02:80:D1 B0:D5:FB:C6:60:6F 30:E0:44:4F:B9:61 | AA18: Pixel 10 Pro, Moonstone, 256GB, AT&T, US | AB18: Yes | AC18: NO | AD18: NO | AE18: NO | AF18: 10ct | AG18: Yes | AH18: Yes | AI18: Yes | AJ18: Yes | AK18: Yes | AL18: NO | AM18: NO | AN18: NO | AO18: BZ5-MP-Colorbox | AP18: BD3A.250721.001.E1 | AR18: MP1.0 | AS18: Android 16 | AT18: G990-08499-32-B | AU18: {=INDEX('label approval artwork'!B:B,MATCH(G18,'label approval artwork'!F:F,0))} -> G990-08504-32-A | AX18: MasterCartonLabel_IMEI-EID_ATT_FIH | AY18: ATT Pallet label -> BTS(Normal case) ATT Pallet Label -> BTO(EDI) | AZ18: G952-05413-003AB
A19: 11 | B19: PVT/MP | C19: Pristine | D19: retail pack | E19: G950-15986-01 | G19: GA09886-US | H19: US - Tmobile | I19: G710-07813-00 | J19: mmWave | K19: CLR1 | L19: BLK | M19: Obsidian | N19: US | O19: G4QUR | P19: UTM | Q19: 840353925212 | R19: 840353925212 | T19: 128GB | U19: TMO | V19: 35 575145 | W19: 35 575145 020000 | X19: 35 575145 319999 | Y19: 04:00:6E:C8:EB:92 64:9D:38:00:00:32 B0:D5:FB:BE:BF:50 30:E0:44:48:18:42 | Z19: 04:00:6E:CA:FE:D1 64:9D:38:02:80:D1 B0:D5:FB:C6:60:6F 30:E0:44:4F:B9:61 | AA19: Pixel 10 Pro, Obsidian, 128GB, TMO, US | AB19: Yes | AC19: NO | AD19: NO | AE19: NO | AF19: 10ct | AG19: Yes | AH19: Yes | AI19: Yes | AJ19: Yes | AK19: Yes | AL19: NO | AM19: NO | AN19: NO | AO19: BZ5-MP-Colorbox | AP19: BD3A.250721.001.E1 | AR19: MP1.0 | AS19: Android 16 | AT19: G990-08499-11-B | AU19: {=INDEX('label approval artwork'!B:B,MATCH(G19,'label approval artwork'!F:F,0))} -> G990-08506-11-A | AX19: MasterCartonLabel_10 pack_TMO | AY19: T-Mobile Pallet Label-> BTO(EDI) T-Mobile Pallet Label-> BTS(Normal case) | AZ19: G952-05413-003AB
A20: 12 | B20: PVT/MP | C20: Pristine | D20: retail pack | E20: G950-15986-02 | G20: GA10293-US | H20: US - Tmobile | I20: G710-07813-00 | J20: mmWave | K20: CLR2 | L20: WHT | M20: Porcelain | N20: US | O20: G4QUR | P20: UTM | Q20: 840353925236 | R20: 840353925236 | T20: 128GB | U20: TMO | V20: 35 575145 | W20: 35 575145 020000 | X20: 35 575145 319999 | Y20: 04:00:6E:C8:EB:92 64:9D:38:00:00:32 B0:D5:FB:BE:BF:50 30:E0:44:48:18:42 | Z20: 04:00:6E:CA:FE:D1 64:9D:38:02:80:D1 B0:D5:FB:C6:60:6F 30:E0:44:4F:B9:61 | AA20: Pixel 10 Pro, Porcelain, 128GB, TMO, US | AB20: Yes | AC20: NO | AD20: NO | AE20: NO | AF20: 10ct | AG20: Yes | AH20: Yes | AI20: Yes | AJ20: Yes | AK20: Yes | AL20: NO | AM20: NO | AN20: NO | AO20: BZ5-MP-Colorbox | AP20: BD3A.250721.001.E1 | AR20: MP1.0 | AS20: Android 16 | AT20: G990-08499-21-B | AU20: {=INDEX('label approval artwork'!B:B,MATCH(G20,'label approval artwork'!F:F,0))} -> G990-08506-21-A | AX20: MasterCartonLabel_10 pack_TMO | AY20: T-Mobile Pallet Label-> BTO(EDI) T-Mobile Pallet Label-> BTS(Normal case) | AZ20: G952-05413-003AB
A21: 13 | B21: PVT/MP | C21: Pristine | D21: retail pack | E21: G950-15986-03 | G21: GA10294-US | H21: US - Tmobile | I21: G710-07813-00 | J21: mmWave | K21: CLR3 | L21: GRY | M21: Moonstone | N21: US | O21: G4QUR | P21: UTM | Q21: 840353925229 | R21: 840353925229 | T21: 128GB | U21: TMO | V21: 35 575145 | W21: 35 575145 020000 | X21: 35 575145 319999 | Y21: 04:00:6E:C8:EB:92 64:9D:38:00:00:32 B0:D5:FB:BE:BF:50 30:E0:44:48:18:42 | Z21: 04:00:6E:CA:FE:D1 64:9D:38:02:80:D1 B0:D5:FB:C6:60:6F 30:E0:44:4F:B9:61 | AA21: Pixel 10 Pro, Moonstone, 128GB, TMO, US | AB21: Yes | AC21: NO | AD21: NO | AE21: NO | AF21: 10ct | AG21: Yes | AH21: Yes | AI21: Yes | AJ21: Yes | AK21: Yes | AL21: NO | AM21: NO | AN21: NO | AO21: BZ5-MP-Colorbox | AP21: BD3A.250721.001.E1 | AR21: MP1.0 | AS21: Android 16 | AT21: G990-08499-31-B | AU21: {=INDEX('label approval artwork'!B:B,MATCH(G21,'label approval artwork'!F:F,0))} -> G990-08506-31-A | AX21: MasterCartonLabel_10 pack_TMO | AY21: T-Mobile Pallet Label-> BTO(EDI) T-Mobile Pallet Label-> BTS(Normal case) | AZ21: G952-05413-003AB
A22: 14 | B22: MP | C22: Pristine | D22: retail pack | E22: G950-18289-01 | G22: GA09898-US | H22: US - Tmobile | I22: G710-07813-10 | J22: mmWave | K22: CLR1 | L22: BLK | M22: Obsidian | N22: US | O22: G4QUR | P22: UTM | Q22: 840353925243 | R22: 840353925243 | T22: 256GB | U22: TMO | V22: 35 575145 | W22: 35 575145 020000 | X22: 35 575145 319999 | Y22: 04:00:6E:C8:EB:92 64:9D:38:00:00:32 B0:D5:FB:BE:BF:50 30:E0:44:48:18:42 | Z22: 04:00:6E:CA:FE:D1 64:9D:38:02:80:D1 B0:D5:FB:C6:60:6F 30:E0:44:4F:B9:61 | AA22: Pixel 10 Pro, Obsidian, 256GB, TMO, US | AB22: Yes | AC22: NO | AD22: NO | AE22: NO | AF22: 10ct | AG22: Yes | AH22: Yes | AI22: Yes | AJ22: Yes | AK22: Yes | AL22: NO | AM22: NO | AN22: NO | AO22: BZ5-MP-Colorbox | AP22: BD3A.250721.001.E1 | AR22: MP1.0 | AS22: Android 16 | AT22: G990-08499-12-B | AU22: {=INDEX('label approval artwork'!B:B,MATCH(G22,'label approval artwork'!F:F,0))} -> G990-08506-12-A | AX22: MasterCartonLabel_10 pack_TMO | AY22: T-Mobile Pallet Label-> BTO(EDI) T-Mobile Pallet Label-> BTS(Normal case) | AZ22: G952-05413-003AB
A23: 15 | B23: MP Cancelled demand | C23: Pristine | D23: retail pack | E23: G950-18289-03 | G23: GA10296-US | H23: US - Tmobile | I23: G710-07813-10 | J23: mmWave | K23: CLR3 | L23: GRY | M23: Moonstone | N23: US | O23: G4QUR | P23: UTM | Q23: 840353925267 | R23: 840353925267 | T23: 256GB | U23: TMO | V23: 35 575145 | W23: 35 575145 020000 | X23: 35 575145 319999 | Y23: 04:00:6E:C8:EB:92 64:9D:38:00:00:32 | Z23: 04:00:6E:CA:FE:D1 64:9D:38:02:80:D1 B0:D5:FB:C6:60:6F | AA23: #N/A | AB23: Yes | AC23: NO | AD23: NO | AE23: NO | AF23: 10ct | AG23: Yes | AH23: Yes | AI23: Yes | AJ23: Yes | AK23: Yes | AL23: NO | AM23: NO | AN23: NO | AP23: BD3A.250721.001.E1 | AR23: MP1.0 | AS23: Android 16 | AT23: G990-08499-32-B | AU23: {=INDEX('label approval artwork'!B:B,MATCH(G23,'label approval artwork'!F:F,0))} -> MP File_TBD | AX23: MasterCartonLabel_10 pack_TMO | AY23: T-Mobile Pallet Label-> BTO(EDI) T-Mobile Pallet Label-> BTS(Normal case) | AZ23: G952-05413-003AB
A24: 16 | B24: IQ | C24: IQ | D24: retail pack | E24: G950-15986-01 | G24: IQGA09187-US | H24: US-VZW | I24: G710-07813-00 | J24: mmWave | K24: CLR1 | L24: BLK | M24: Obsidian | N24: US | O24: G4QUR | P24: UVZ | R24: 840353936584 | T24: 128GB | U24: VZW | V24: 35 531042 | W24: 35 531042 020000 35 531042 320000x | X24: 35 531042 319999 35 531042 619999x | Y24: 04:00:6E:C8:EB:92 64:9D:38:00:00:32 B0:D5:FB:BE:BF:50 30:E0:44:48:18:42 | Z24: 04:00:6E:CA:FE:D1 64:9D:38:02:80:D1 B0:D5:FB:C6:60:6F 30:E0:44:4F:B9:61 | AA24: Pixel 10 Pro, Obsidian, 128GB, VZW, US, IQ | AB24: Yes | AC24: NO | AD24: NO | AE24: NO | AF24: 10ct | AG24: Yes | AH24: Yes | AI24: Yes | AJ24: Yes | AK24: Yes | AL24: NO | AM24: NO | AN24: NO | AO24: BZ5-MP-Colorbox | AP24: BD3A.250721.001.E1 | AR24: MP1.0 | AS24: Android 16 | AT24: G990-08499-11-B | AU24: {=INDEX('label approval artwork'!B:B,MATCH(G24,'label approval artwork'!F:F,0))} -> G990-08505-11-A | AX24: VZN Master Carton Label | AY24: VZN Pallet Label -> BTS(Normal case) | AZ24: G952-05413-003AB
A25: 17 | B25: IQ | C25: IQ | D25: retail pack | E25: G950-15986-02 | G25: IQGA10275-US | H25: US-VZW | I25: G710-07813-00 | J25: mmWave | K25: CLR2 | L25: WHT | M25: Porcelain | N25: US | O25: G4QUR | P25: UVZ | R25: 840353936591 | T25: 128GB | U25: VZW | V25: 35 531042 | W25: 35 531042 020000 35 531042 320000x | X25: 35 531042 319999 35 531042 619999x | Y25: 04:00:6E:C8:EB:92 64:9D:38:00:00:32 B0:D5:FB:BE:BF:50 30:E0:44:48:18:42 | Z25: 04:00:6E:CA:FE:D1 64:9D:38:02:80:D1 B0:D5:FB:C6:60:6F 30:E0:44:4F:B9:61 | AA25: Pixel 10 Pro, Porcelain, 128GB, VZW, US, IQ | AB25: Yes | AC25: NO | AD25: NO | AE25: NO | AF25: 10ct | AG25: Yes | AH25: Yes | AI25: Yes | AJ25: Yes | AK25: Yes | AL25: NO | AM25: NO | AN25: NO | AO25: BZ5-MP-Colorbox | AP25: BD3A.250721.001.E1 | AR25: MP1.0 | AS25: Android 16 | AT25: G990-08499-21-B | AU25: {=INDEX('label approval artwork'!B:B,MATCH(G25,'label approval artwork'!F:F,0))} -> G990-08505-11-A | AX25: VZN Master Carton Label | AY25: VZN Pallet Label -> BTS(Normal case) | AZ25: G952-05413-003AB
A26: 18 | B26: IQ | C26: IQ | D26: retail pack | E26: G950-15986-03 | G26: IQGA10276-US | H26: US-VZW | I26: G710-07813-00 | J26: mmWave | K26: CLR3 | L26: GRY | M26: Moonstone | N26: US | O26: G4QUR | P26: UVZ | R26: 840353936607 | T26: 128GB | U26: VZW | V26: 35 531042 | W26: 35 531042 020000 35 531042 320000x | X26: 35 531042 319999 35 531042 619999x | Y26: 04:00:6E:C8:EB:92 64:9D:38:00:00:32 B0:D5:FB:BE:BF:50 30:E0:44:48:18:42 | Z26: 04:00:6E:CA:FE:D1 64:9D:38:02:80:D1 B0:D5:FB:C6:60:6F 30:E0:44:4F:B9:61 | AA26: Pixel 10 Pro, Moonstone, 128GB, VZW, US, IQ | AB26: Yes | AC26: NO | AD26: NO | AE26: NO | AF26: 10ct | AG26: Yes | AH26: Yes | AI26: Yes | AJ26: Yes | AK26: Yes | AL26: NO | AM26: NO | AN26: NO | AO26: BZ5-MP-Colorbox | AP26: BD3A.250721.001.E1 | AR26: MP1.0 | AS26: Android 16 | AT26: G990-08499-31-B | AU26: {=INDEX('label approval artwork'!B:B,MATCH(G26,'label approval artwork'!F:F,0))} -> G990-08505-11-A | AX26: VZN Master Carton Label | AY26: VZN Pallet Label -> BTS(Normal case) | AZ26: G952-05413-003AB
A27: 19 | B27: IQ | C27: IQ | D27: retail pack | E27: G950-18289-01 | G27: IQGA09896-US | H27: US-VZW | I27: G710-07813-10 | J27: mmWave | K27: CLR1 | L27: BLK | M27: Obsidian | N27: US | O27: G4QUR | P27: UVZ | R27: 0840353936614 | T27: 256GB | U27: VZW | V27: 35 531042 | W27: 35 531042 020000 35 531042 320000x | X27: 35 531042 319999 35 531042 619999x | Y27: 04:00:6E:C8:EB:92 64:9D:38:00:00:32 B0:D5:FB:BE:BF:50 30:E0:44:48:18:42 | Z27: 04:00:6E:CA:FE:D1 64:9D:38:02:80:D1 B0:D5:FB:C6:60:6F 30:E0:44:4F:B9:61 | AA27: Pixel 10 Pro, Obsidian, 256GB, VZW, US, IQ | AB27: Yes | AC27: NO | AD27: NO | AE27: NO | AF27: 10ct | AG27: Yes | AH27: Yes | AI27: Yes | AJ27: Yes | AK27: Yes | AL27: NO | AM27: NO | AN27: NO | AO27: BZ5-MP-Colorbox | AP27: BD3A.250721.001.E1 | AR27: MP1.0 | AS27: Android 16 | AT27: G990-08499-12-B | AU27: {=INDEX('label approval artwork'!B:B,MATCH(G27,'label approval artwork'!F:F,0))} -> G990-08505-11-A | AX27: VZN Master Carton Label | AY27: VZN Pallet Label -> BTS(Normal case) | AZ27: G952-05413-003AB
A28: 20 | B28: IQ | C28: IQ | D28: retail pack | E28: G950-18289-02 | G28: IQGA10277-US | H28: US-VZW | I28: G710-07813-10 | J28: mmWave | K28: CLR2 | L28: WHT | M28: Porcelain | N28: US | O28: G4QUR | P28: UVZ | R28: 840353936621 | T28: 256GB | U28: VZW | V28: 35 531042 | W28: 35 531042 020000 35 531042 320000x | X28: 35 531042 319999 35 531042 619999x | Y28: 04:00:6E:C8:EB:92 64:9D:38:00:00:32 B0:D5:FB:BE:BF:50 30:E0:44:48:18:42 | Z28: 04:00:6E:CA:FE:D1 64:9D:38:02:80:D1 B0:D5:FB:C6:60:6F 30:E0:44:4F:B9:61 | AA28: Pixel 10 Pro, Porcelain, 256GB, VZW, US, IQ | AB28: Yes | AC28: NO | AD28: NO | AE28: NO | AF28: 10ct | AG28: Yes | AH28: Yes | AI28: Yes | AJ28: Yes | AK28: Yes | AL28: NO | AM28: NO | AN28: NO | AO28: BZ5-MP-Colorbox | AR28: MP1.0 | AS28: Android 16 | AT28: G990-08499-22-B | AU28: {=INDEX('label approval artwork'!B:B,MATCH(G28,'label approval artwork'!F:F,0))} -> G990-08505-11-A | AX28: VZN Master Carton Label | AY28: VZN Pallet Label -> BTS(Normal case) | AZ28: G952-05413-003AB
A29: 21 | B29: IQ | C29: IQ | D29: retail pack | E29: G950-18289-03 | G29: IQGA10278-US | H29: US-VZW | I29: G710-07813-10 | J29: mmWave | K29: CLR3 | L29: GRY | M29: Moonstone | N29: US | O29: G4QUR | P29: UVZ | R29: 840353936638 | T29: 256GB | U29: VZW | V29: 35 531042 | W29: 35 531042 020000 35 531042 320000x | X29: 35 531042 319999 35 531042 619999x | Y29: 04:00:6E:C8:EB:92 64:9D:38:00:00:32 B0:D5:FB:BE:BF:50 30:E0:44:48:18:42 | Z29: 04:00:6E:CA:FE:D1 64:9D:38:02:80:D1 B0:D5:FB:C6:60:6F 30:E0:44:4F:B9:61 | AA29: Pixel 10 Pro, Moonstone, 256GB, VZW, US, IQ | AB29: Yes | AC29: NO | AD29: NO | AE29: NO | AF29: 10ct | AG29: Yes | AH29: Yes | AI29: Yes | AJ29: Yes | AK29: Yes | AL29: NO | AM29: NO | AN29: NO | AO29: BZ5-MP-Colorbox | AP29: BD3A.250721.001.E1 | AR29: MP1.0 | AS29: Android 16 | AT29: G990-08499-32-B | AU29: {=INDEX('label approval artwork'!B:B,MATCH(G29,'label approval artwork'!F:F,0))} -> G990-08505-11-A | AX29: VZN Master Carton Label | AY29: VZN Pallet Label -> BTS(Normal case) | AZ29: G952-05413-003AB
A30: 22 | B30: IQ | C30: IQ | D30: retail pack | E30: G950-18289-04 | G30: IQGA10279-US | H30: US-VZW | I30: G710-07813-10 | J30: mmWave | K30: CLR4 | L30: GRN | M30: Jade | N30: US | O30: G4QUR | P30: UVZ | R30: 840353936645 | T30: 256GB | U30: VZW | V30: 35 531042 | W30: 35 531042 020000 35 531042 320000x | X30: 35 531042 319999 35 531042 619999x | Y30: 04:00:6E:C8:EB:92 64:9D:38:00:00:32 B0:D5:FB:BE:BF:50 30:E0:44:48:18:42 | Z30: 04:00:6E:CA:FE:D1 64:9D:38:02:80:D1 B0:D5:FB:C6:60:6F 30:E0:44:4F:B9:61 | AA30: Pixel 10 Pro, Jade, 256GB, VZW, US, IQ | AB30: Yes | AC30: NO | AD30: NO | AE30: NO | AF30: 10ct | AG30: Yes | AH30: Yes | AI30: Yes | AJ30: Yes | AK30: Yes | AL30: NO | AM30: NO | AN30: NO | AO30: BZ5-MP-Colorbox | AP30: BD3A.250721.001.E1 | AR30: MP1.0 | AS30: Android 16 | AT30: G990-08499-42-B | AU30: {=INDEX('label approval artwork'!B:B,MATCH(G30,'label approval artwork'!F:F,0))} -> G990-08505-11-A | AX30: VZN Master Carton Label | AY30: VZN Pallet Label -> BTS(Normal case) | AZ30: G952-05413-003AB
A31: 23 | B31: IQ | C31: IQ | D31: retail pack | E31: G950-18291-01 | G31: IQGA09905-US | H31: US-VZW | I31: G710-07813-20 | J31: mmWave | K31: CLR1 | L31: BLK | M31: Obsidian | N31: US | O31: G4QUR | P31: UVZ | R31: 840353936652 | T31: 512GB | U31: VZW | V31: 35 531042 | W31: 35 531042 020000 35 531042 320000x | X31: 35 531042 319999 35 531042 619999x | Y31: 04:00:6E:C8:EB:92 64:9D:38:00:00:32 B0:D5:FB:BE:BF:50 30:E0:44:48:18:42 | Z31: 04:00:6E:CA:FE:D1 64:9D:38:02:80:D1 B0:D5:FB:C6:60:6F 30:E0:44:4F:B9:61 | AA31: Pixel 10 Pro, Obsidian, 512GB, VZW, US, IQ | AB31: Yes | AC31: NO | AD31: NO | AE31: NO | AF31: 10ct | AG31: Yes | AH31: Yes | AI31: Yes | AJ31: Yes | AK31: Yes | AL31: NO | AM31: NO | AN31: NO | AO31: BZ5-MP-Colorbox | AP31: BD3A.250721.001.E1 | AR31: MP1.0 | AS31: Android 16 | AT31: G990-08499-13-B | AU31: {=INDEX('label approval artwork'!B:B,MATCH(G31,'label approval artwork'!F:F,0))} -> G990-08505-11-A | AX31: VZN Master Carton Label | AY31: VZN Pallet Label -> BTS(Normal case) | AZ31: G952-05413-003AB
A32: 24 | B32: IQ | C32: IQ | D32: retail pack | E32: G950-18291-02 | G32: IQGA10280-US | H32: US-VZW | I32: G710-07813-20 | J32: mmWave | K32: CLR2 | L32: WHT | M32: Porcelain | N32: US | O32: G4QUR | P32: UVZ | R32: 840353936669 | T32: 512GB | U32: VZW | V32: 35 531042 | W32: 35 531042 020000 35 531042 320000x | X32: 35 531042 319999 35 531042 619999x | Y32: 04:00:6E:C8:EB:92 64:9D:38:00:00:32 B0:D5:FB:BE:BF:50 30:E0:44:48:18:42 | Z32: 04:00:6E:CA:FE:D1 64:9D:38:02:80:D1 B0:D5:FB:C6:60:6F 30:E0:44:4F:B9:61 | AA32: Pixel 10 Pro, Porcelain, 512GB, VZW, US, IQ | AB32: Yes | AC32: NO | AD32: NO | AE32: NO | AF32: 10ct | AG32: Yes | AH32: Yes | AI32: Yes | AJ32: Yes | AK32: Yes | AL32: NO | AM32: NO | AN32: NO | AO32: BZ5-MP-Colorbox | AR32: MP1.0 | AS32: Android 16 | AT32: G990-08499-23-B | AU32: {=INDEX('label approval artwork'!B:B,MATCH(G32,'label approval artwork'!F:F,0))} -> G990-08505-11-A | AX32: VZN Master Carton Label | AY32: VZN Pallet Label -> BTS(Normal case) | AZ32: G952-05413-003AB
A33: 25 | B33: IQ | C33: IQ | D33: retail pack | E33: G950-18291-03 | G33: IQGA10281-US | H33: US-VZW | I33: G710-07813-20 | J33: mmWave | K33: CLR3 | L33: GRY | M33: Moonstone | N33: US | O33: G4QUR | P33: UVZ | R33: 840353936676 | T33: 512GB | U33: VZW | V33: 35 531042 | W33: 35 531042 020000 35 531042 320000x | X33: 35 531042 319999 35 531042 619999x | Y33: 04:00:6E:C8:EB:92 64:9D:38:00:00:32 B0:D5:FB:BE:BF:50 30:E0:44:48:18:42 | Z33: 04:00:6E:CA:FE:D1 64:9D:38:02:80:D1 B0:D5:FB:C6:60:6F 30:E0:44:4F:B9:61 | AA33: Pixel 10 Pro, Moonstone, 512GB, VZW, US, IQ | AB33: Yes | AC33: NO | AD33: NO | AE33: NO | AF33: 10ct | AG33: Yes | AH33: Yes | AI33: Yes | AJ33: Yes | AK33: Yes | AL33: NO | AM33: NO | AN33: NO | AO33: BZ5-MP-Colorbox | AP33: BD3A.250721.001.E1 | AR33: MP1.0 | AS33: Android 16 | AT33: G990-08499-33-B | AU33: {=INDEX('label approval artwork'!B:B,MATCH(G33,'label approval artwork'!F:F,0))} -> G990-08505-11-A | AX33: VZN Master Carton Label | AY33: VZN Pallet Label -> BTS(Normal case) | AZ33: G952-05413-003AB
A34: 26 | B34: IQ | C34: IQ | D34: retail pack | E34: G950-18291-04 | G34: IQGA10282-US | H34: US-VZW | I34: G710-07813-20 | J34: mmWave | K34: CLR4 | L34: GRN | M34: Jade | N34: US | O34: G4QUR | P34: UVZ | R34: 840353936683 | T34: 512GB | U34: VZW | V34: 35 531042 | W34: 35 531042 020000 35 531042 320000x | X34: 35 531042 319999 35 531042 619999x | Y34: 04:00:6E:C8:EB:92 64:9D:38:00:00:32 B0:D5:FB:BE:BF:50 30:E0:44:48:18:42 | Z34: 04:00:6E:CA:FE:D1 64:9D:38:02:80:D1 B0:D5:FB:C6:60:6F 30:E0:44:4F:B9:61 | AA34: Pixel 10 Pro, Jade, 512GB, VZW, US, IQ | AB34: Yes | AC34: NO | AD34: NO | AE34: NO | AF34: 10ct | AG34: Yes | AH34: Yes | AI34: Yes | AJ34: Yes | AK34: Yes | AL34: NO | AM34: NO | AN34: NO | AO34: BZ5-MP-Colorbox | AR34: MP1.0 | AS34: Android 16 | AT34: G990-08499-43-B | AU34: {=INDEX('label approval artwork'!B:B,MATCH(G34,'label approval artwork'!F:F,0))} -> G990-08505-11-A | AX34: VZN Master Carton Label | AY34: VZN Pallet Label -> BTS(Normal case) | AZ34: G952-05413-003AB
A35: 27 | B35: IQ | C35: IQ | D35: retail pack | E35: G950-18293-01 | G35: IQGA09930-US | H35: US-VZW | I35: G710-07813-30 | J35: mmWave | K35: CLR1 | L35: BLK | M35: Obsidian | N35: US | O35: G4QUR | P35: UVZ | R35: 840353936690 | T35: 1TB | U35: VZW | V35: 35 531042 | W35: 35 531042 020000 35 531042 320000x | X35: 35 531042 319999 35 531042 619999x | Y35: 04:00:6E:C8:EB:92 64:9D:38:00:00:32 B0:D5:FB:BE:BF:50 30:E0:44:48:18:42 | Z35: 04:00:6E:CA:FE:D1 64:9D:38:02:80:D1 B0:D5:FB:C6:60:6F 30:E0:44:4F:B9:61 | AA35: Pixel 10 Pro, Obsidian, 1TB, VZW, US, IQ | AB35: Yes | AC35: NO | AD35: NO | AE35: NO | AF35: 10ct | AG35: Yes | AH35: Yes | AI35: Yes | AJ35: Yes | AK35: Yes | AL35: NO | AM35: NO | AN35: NO | AO35: BZ5-MP-Colorbox | AR35: MP1.0 | AS35: Android 16 | AT35: G990-08499-14-B | AU35: {=INDEX('label approval artwork'!B:B,MATCH(G35,'label approval artwork'!F:F,0))} -> G990-08505-11-A | AX35: VZN Master Carton Label | AY35: VZN Pallet Label -> BTS(Normal case) | AZ35: G952-05413-003AB
A36: 28 | B36: IQ | C36: IQ | D36: retail pack | E36: G950-18293-03 | G36: IQGA10283-US | H36: US-VZW | I36: G710-07813-30 | J36: mmWave | K36: CLR3 | L36: GRY | M36: Moonstone | N36: US | O36: G4QUR | P36: UVZ | R36: 840353936706 | T36: 1TB | U36: VZW | V36: 35 531042 | W36: 35 531042 020000 35 531042 320000x | X36: 35 531042 319999 35 531042 619999x | Y36: 04:00:6E:C8:EB:92 64:9D:38:00:00:32 B0:D5:FB:BE:BF:50 30:E0:44:48:18:42 | Z36: 04:00:6E:CA:FE:D1 64:9D:38:02:80:D1 B0:D5:FB:C6:60:6F 30:E0:44:4F:B9:61 | AA36: Pixel 10 Pro, Moonstone, 1TB, VZW, US, IQ | AB36: Yes | AC36: NO | AD36: NO | AE36: NO | AF36: 10ct | AG36: Yes | AH36: Yes | AI36: Yes | AJ36: Yes | AK36: Yes | AL36: NO | AM36: NO | AN36: NO | AO36: BZ5-MP-Colorbox | AR36: MP1.0 | AS36: Android 16 | AT36: G990-08499-34-B | AU36: {=INDEX('label approval artwork'!B:B,MATCH(G36,'label approval artwork'!F:F,0))} -> G990-08505-11-A | AX36: VZN Master Carton Label | AY36: VZN Pallet Label -> BTS(Normal case) | AZ36: G952-05413-003AB
A37: 29 | B37: CLNR | C37: CLNR | D37: builk pack | E37: G950-15986-01 | G37: CLNRGOGA09187 | H37: US-VZW | I37: G710-07813-00 | J37: mmWave | K37: CLR1 | L37: BLK | M37: Obsidian | N37: US | O37: G4QUR | P37: UVZ | R37: 840353936713 | T37: 128GB | U37: VZW | V37: 35 531042 | W37: 35 531042 020000 35 531042 320000x | X37: 35 531042 319999 35 531042 619999x | Y37: 04:00:6E:C8:EB:92 64:9D:38:00:00:32 B0:D5:FB:BE:BF:50 30:E0:44:48:18:42 | Z37: 04:00:6E:CA:FE:D1 64:9D:38:02:80:D1 B0:D5:FB:C6:60:6F 30:E0:44:4F:B9:61 | AA37: Pixel 10 Pro, Obsidian, 128GB, VZW, US, FRU | AB37: Yes | AC37: NO | AD37: NO | AE37: NO | AF37: 30ct | AG37: NO | AH37: NO | AI37: NO | AJ37: NO | AK37: NO | AL37: NO | AM37: NO | AN37: NO | AO37: BZ5-MP-ENG-VZN | AP37: BD3A.250721.001.E1 | AR37: MP1.0 | AS37: Android 16 | AT37: {=INDEX('label approval artwork'!A:A,MATCH(G37,'label approval artwork'!F:F,0))} -> #VALUE! | AU37: {=INDEX('label approval artwork'!B:B,MATCH(G37,'label approval artwork'!F:F,0))} -> #VALUE! | AX37: VZN Master Carton Label | AY37: VZN Pallet Label -> BTS(Normal case)
A38: 30 | B38: CLNR | C38: CLNR | D38: builk pack | E38: G950-15986-03 | G38: CLNRGOGA10276 | H38: US-VZW | I38: G710-07813-00 | J38: mmWave | K38: CLR3 | L38: GRY | M38: Moonstone | N38: US | O38: G4QUR | P38: UVZ | R38: 840353936836 | T38: 128GB | U38: VZW | V38: 35 531042 | W38: 35 531042 020000 35 531042 320000x | X38: 35 531042 319999 35 531042 619999x | Y38: 04:00:6E:C8:EB:92 64:9D:38:00:00:32 B0:D5:FB:BE:BF:50 30:E0:44:48:18:42 | Z38: 04:00:6E:CA:FE:D1 64:9D:38:02:80:D1 B0:D5:FB:C6:60:6F 30:E0:44:4F:B9:61 | AA38: Pixel 10 Pro, Moonstone, 128GB, VZW, US, FRU | AB38: Yes | AC38: NO | AD38: NO | AE38: NO | AF38: 30ct | AG38: NO | AH38: NO | AI38: NO | AJ38: NO | AK38: NO | AL38: NO | AM38: NO | AN38: NO | AO38: BZ5-MP-ENG-VZN | AP38: BD3A.250721.001.E1 | AR38: MP1.0 | AS38: Android 16 | AT38: {=INDEX('label approval artwork'!A:A,MATCH(G38,'label approval artwork'!F:F,0))} -> #VALUE! | AU38: {=INDEX('label approval artwork'!B:B,MATCH(G38,'label approval artwork'!F:F,0))} -> #VALUE! | AX38: VZN Master Carton Label | AY38: VZN Pallet Label -> BTS(Normal case)
A39: 31 | B39: CLNR | C39: CLNR | D39: builk pack | E39: G950-18289-01 | G39: CLNRGOGA09896 | H39: US-VZW | I39: G710-07813-10 | J39: mmWave | K39: CLR1 | L39: BLK | M39: Obsidian | N39: US | O39: G4QUR | P39: UVZ | R39: 840353936898 | T39: 256GB | U39: VZW | V39: 35 531042 | W39: 35 531042 020000 35 531042 320000x | X39: 35 531042 319999 35 531042 619999x | Y39: 04:00:6E:C8:EB:92 64:9D:38:00:00:32 B0:D5:FB:BE:BF:50 30:E0:44:48:18:42 | Z39: 04:00:6E:CA:FE:D1 64:9D:38:02:80:D1 B0:D5:FB:C6:60:6F 30:E0:44:4F:B9:61 | AA39: Pixel 10 Pro, Obsidian, 256GB, VZW, US, FRU | AB39: Yes | AC39: NO | AD39: NO | AE39: NO | AF39: 30ct | AG39: NO | AH39: NO | AI39: NO | AJ39: NO | AK39: NO | AL39: NO | AM39: NO | AN39: NO | AO39: BZ5-MP-ENG-VZN | AP39: BD3A.250721.001.E1 | AR39: MP1.0 | AS39: Android 16 | AT39: {=INDEX('label approval artwork'!A:A,MATCH(G39,'label approval artwork'!F:F,0))} -> #VALUE! | AU39: {=INDEX('label approval artwork'!B:B,MATCH(G39,'label approval artwork'!F:F,0))} -> #VALUE! | AX39: VZN Master Carton Label | AY39: VZN Pallet Label -> BTS(Normal case)
A40: 32 | B40: CLNR | C40: CLNR | D40: builk pack | E40: G950-18289-03 | G40: CLNRGOGA10278 | H40: US-VZW | I40: G710-07813-10 | J40: mmWave | K40: CLR3 | L40: GRY | M40: Moonstone | N40: US | O40: G4QUR | P40: UVZ | R40: 840353936911 | T40: 256GB | U40: VZW | V40: 35 531042 | W40: 35 531042 020000 35 531042 320000x | X40: 35 531042 319999 35 531042 619999x | Y40: 04:00:6E:C8:EB:92 64:9D:38:00:00:32 B0:D5:FB:BE:BF:50 30:E0:44:48:18:42 | Z40: 04:00:6E:CA:FE:D1 64:9D:38:02:80:D1 B0:D5:FB:C6:60:6F 30:E0:44:4F:B9:61 | AA40: Pixel 10 Pro, Moonstone, 256GB, VZW, US, FRU | AB40: Yes | AC40: NO | AD40: NO | AE40: NO | AF40: 30ct | AG40: NO | AH40: NO | AI40: NO | AJ40: NO | AK40: NO | AL40: NO | AM40: NO | AN40: NO | AO40: BZ5-MP-ENG-VZN | AP40: BD3A.250721.001.E1 | AR40: MP1.0 | AS40: Android 16 | AT40: {=INDEX('label approval artwork'!A:A,MATCH(G40,'label approval artwork'!F:F,0))} -> #VALUE! | AU40: {=INDEX('label approval artwork'!B:B,MATCH(G40,'label approval artwork'!F:F,0))} -> #VALUE! | AX40: VZN Master Carton Label | AY40: VZN Pallet Label -> BTS(Normal case)
A41: 33 | B41: CLNR | C41: CLNR | D41: builk pack | E41: G950-18289-04 | G41: CLNRGOGA10279 | H41: US-VZW | I41: G710-07813-10 | J41: mmWave | K41: CLR4 | L41: GRN | M41: Jade | N41: US | O41: G4QUR | P41: UVZ | R41: 840353936928 | T41: 256GB | U41: VZW | V41: 35 531042 | W41: 35 531042 020000 35 531042 320000x | X41: 35 531042 319999 35 531042 619999x | Y41: 04:00:6E:C8:EB:92 64:9D:38:00:00:32 B0:D5:FB:BE:BF:50 30:E0:44:48:18:42 | Z41: 04:00:6E:CA:FE:D1 64:9D:38:02:80:D1 B0:D5:FB:C6:60:6F 30:E0:44:4F:B9:61 | AA41: Pixel 10 Pro, Jade, 256GB, VZW, US, FRU | AB41: Yes | AC41: NO | AD41: NO | AE41: NO | AF41: 30ct | AG41: NO | AH41: NO | AI41: NO | AJ41: NO | AK41: NO | AL41: NO | AM41: NO | AN41: NO | AO41: BZ5-MP-ENG-VZN | AP41: BD3A.250721.001.E1 | AR41: MP1.0 | AS41: Android 16 | AT41: {=INDEX('label approval artwork'!A:A,MATCH(G41,'label approval artwork'!F:F,0))} -> #VALUE! | AU41: {=INDEX('label approval artwork'!B:B,MATCH(G41,'label approval artwork'!F:F,0))} -> #VALUE! | AX41: VZN Master Carton Label | AY41: VZN Pallet Label -> BTS(Normal case)
...

Sheet label approval artwork
A2: MP BOB ARTWORK | B2: MP Retail Artwork | C2: =IFERROR(__xludf.DUMMYFUNCTION("IMPORTRANGE(""https://docs.google.com/spreadsheets/d/15lzIx3irnFzzB1FWzssnBG7N0TKQQGt1hWrVTnBNvgM/edit?gid=1763328259#gid=1763328259"",""P-68 Master Approval(for All SKU not include ATT/VZNTMO)!A4:AZ200"")"),"Item") -> Item | D2: =IFERROR(__xludf.DUMMYFUNCTION("""COMPUTED_VALUE"""),"Stage") -> Stage | E2: =IFERROR(__xludf.DUMMYFUNCTION("""COMPUTED_VALUE"""),"Purpose") -> Purpose | F2: =IFERROR(__xludf.DUMMYFUNCTION("""COMPUTED_VALUE"""),"Sale SKU") -> Sale SKU | G2: =IFERROR(__xludf.DUMMYFUNCTION("""COMPUTED_VALUE"""),"Model# 產品型號#") -> Model# 產品型號# | H2: =IFERROR(__xludf.DUMMYFUNCTION("""COMPUTED_VALUE"""),"UPC CODE-12") -> UPC CODE-12 | I2: =IFERROR(__xludf.DUMMYFUNCTION("""COMPUTED_VALUE"""),"EAN CODE-13") -> EAN CODE-13 | J2: =IFERROR(__xludf.DUMMYFUNCTION("""COMPUTED_VALUE"""),"SAP/SKU ID for Retail label") -> SAP/SKU ID for Retail label | K2: =IFERROR(__xludf.DUMMYFUNCTION("""COMPUTED_VALUE"""),"Master Carton Label GPN & Rev") -> Master Carton Label GPN & Rev | L2: =IFERROR(__xludf.DUMMYFUNCTION("""COMPUTED_VALUE"""),"Pallet Label GPN & Rev") -> Pallet Label GPN & Rev | M2: =IFERROR(__xludf.DUMMYFUNCTION("""COMPUTED_VALUE"""),"BOB Artwork GPN & Rev") -> BOB Artwork GPN & Rev | N2: =IFERROR(__xludf.DUMMYFUNCTION("""COMPUTED_VALUE"""),"IN MRP Label") -> IN MRP Label | O2: =IFERROR(__xludf.DUMMYFUNCTION("""COMPUTED_VALUE"""),"Retail Artwork GPN & Rev") -> Retail Artwork GPN & Rev | P2: =IFERROR(__xludf.DUMMYFUNCTION("""COMPUTED_VALUE"""),"Revison") -> Revison | Q2: =IFERROR(__xludf.DUMMYFUNCTION("""COMPUTED_VALUE"""),"Memory ") -> Memory | R2: =IFERROR(__xludf.DUMMYFUNCTION("""COMPUTED_VALUE"""),"Color Name from sleeve template use") -> Color Name from sleeve template use | S2: =IFERROR(__xludf.DUMMYFUNCTION("""COMPUTED_VALUE"""),"Color ID from Znext") -> Color ID from Znext | T2: =IFERROR(__xludf.DUMMYFUNCTION("""COMPUTED_VALUE"""),"SKU") -> SKU | U2: =IFERROR(__xludf.DUMMYFUNCTION("""COMPUTED_VALUE"""),"Description") -> Description | V2: =IFERROR(__xludf.DUMMYFUNCTION("""COMPUTED_VALUE"""),"Real Description") -> Real Description | W2: =IFERROR(__xludf.DUMMYFUNCTION("""COMPUTED_VALUE"""),"P-65 Inform NPI OPM if no 65 days buffer") -> P-65 Inform NPI OPM if no 65 days buffer | X2: =IFERROR(__xludf.DUMMYFUNCTION("""COMPUTED_VALUE"""),"Day P Ok2pack") -> Day P Ok2pack | Y2: =IFERROR(__xludf.DUMMYFUNCTION("""COMPUTED_VALUE"""),"Day P-50 EPM release RevA Date (CM Receive from G +1 day)") -> Day P-50 EPM release RevA Date (CM Receive from G +1 day) | Z2: =IFERROR(__xludf.DUMMYFUNCTION("""COMPUTED_VALUE"""),"EPM Confirm done with ✅") -> EPM Confirm done with ✅ | AA2: =IFERROR(__xludf.DUMMYFUNCTION("""COMPUTED_VALUE"""),"Day P-50 PPO release RevA Date (CM Receive from G +1 day)") -> Day P-50 PPO release RevA Date (CM Receive from G +1 day) | AB2: =IFERROR(__xludf.DUMMYFUNCTION("""COMPUTED_VALUE"""),"PPO Confirm done with ✅") -> PPO Confirm done with ✅ | AC2: =IFERROR(__xludf.DUMMYFUNCTION("""COMPUTED_VALUE"""),"P-43 Template Mock-up") -> P-43 Template Mock-up | AD2: =IFERROR(__xludf.DUMMYFUNCTION("""COMPUTED_VALUE"""),"P-43 Packing PD/PE Buy-off") -> P-43 Packing PD/PE Buy-off | AE2: =IFERROR(__xludf.DUMMYFUNCTION("""COMPUTED_VALUE"""),"P-37 Retail Label Photo in Approval Format(+link)") -> P-37 Retail Label Photo in Approval Format(+link) | AF2: =IFERROR(__xludf.DUMMYFUNCTION("""COMPUTED_VALUE"""),"P-37 MRP Label Photo in Approval Format(+link)") -> P-37 MRP Label Photo in Approval Format(+link) | AG2: =IFERROR(__xludf.DUMMYFUNCTION("""COMPUTED_VALUE"""),"P-37 Carton/Pallet Label (SKU + link) ") -> P-37 Carton/Pallet Label (SKU + link) | AH2: =IFERROR(__xludf.DUMMYFUNCTION("""COMPUTED_VALUE"""),"P-37 BOB Sleeve (SKU + link)") -> P-37 BOB Sleeve (SKU + link) | AI2: =IFERROR(__xludf.DUMMYFUNCTION("""COMPUTED_VALUE"""),"P-36 QA Buy-off (PDF/SKU with link)") -> P-36 QA Buy-off (PDF/SKU with link) | AJ2: =IFERROR(__xludf.DUMMYFUNCTION("""COMPUTED_VALUE"""),"P-36 Date") -> P-36 Date | AK2: =IFERROR(__xludf.DUMMYFUNCTION("""COMPUTED_VALUE"""),"P-29 EPM soft Approval (RAP and BOB artwork)") -> P-29 EPM soft Approval (RAP and BOB artwork) | AL2: =IFERROR(__xludf.DUMMYFUNCTION("""COMPUTED_VALUE"""),"P-29 EPM soft approved ✅") -> P-29 EPM soft approved ✅ | AM2: =IFERROR(__xludf.DUMMYFUNCTION("""COMPUTED_VALUE"""),"P-30 EPM BOB POR (Rev A) Soft approved ✅") -> P-30 EPM BOB POR (Rev A) Soft approved ✅ | AN2: =IFERROR(__xludf.DUMMYFUNCTION("""COMPUTED_VALUE"""),"P-29 LSL soft approval (Carton & Pallet label)") -> P-29 LSL soft approval (Carton & Pallet label) | AO2: =IFERROR(__xludf.DUMMYFUNCTION("""COMPUTED_VALUE"""),"P-29 LSL soft approved ✅") -> P-29 LSL soft approved ✅ | AP2: =IFERROR(__xludf.DUMMYFUNCTION("""COMPUTED_VALUE"""),"P-26 Origin Logistic Physical Label needed?(Y/N)") -> P-26 Origin Logistic Physical Label needed?(Y/N) | AQ2: =IFERROR(__xludf.DUMMYFUNCTION("""COMPUTED_VALUE"""),"Origin Logistic Tracking #") -> Origin Logistic Tracking # | AR2: =IFERROR(__xludf.DUMMYFUNCTION("""COMPUTED_VALUE"""),"P-29 Label Approval ( DRI Name -QRcode Required)") -> P-29 Label Approval ( DRI Name -QRcode Required) | AS2: =IFERROR(__xludf.DUMMYFUNCTION("""COMPUTED_VALUE"""),"P-29 QRcode DRI approved ✅") -> P-29 QRcode DRI approved ✅ | AT2: =IFERROR(__xludf.DUMMYFUNCTION("""COMPUTED_VALUE"""),"P-29 QRcode Physical sample needed?(Y/N)") -> P-29 QRcode Physical sample needed?(Y/N) | AU2: =IFERROR(__xludf.DUMMYFUNCTION("""COMPUTED_VALUE"""),"QRcode DRI Tracking #") -> QRcode DRI Tracking # | AV2: =IFERROR(__xludf.DUMMYFUNCTION("""COMPUTED_VALUE"""),"P-29 Label Approval (PGM - Carrier info Required)") -> P-29 Label Approval (PGM - Carrier info Required) | AW2: =IFERROR(__xludf.DUMMYFUNCTION("""COMPUTED_VALUE"""),"P-29 PGM approved ✅") -> P-29 PGM approved ✅ | AX2: =IFERROR(__xludf.DUMMYFUNCTION("""COMPUTED_VALUE"""),"P-26 PGM Physical Label needed?(Y/N)") -> P-26 PGM Physical Label needed?(Y/N) | AY2: =IFERROR(__xludf.DUMMYFUNCTION("""COMPUTED_VALUE"""),"PGM Tracking #") -> PGM Tracking # | AZ2: =IFERROR(__xludf.DUMMYFUNCTION("""COMPUTED_VALUE"""),"P-3 Origin Logistic Hard copy approval") -> P-3 Origin Logistic Hard copy approval | BA2: =IFERROR(__xludf.DUMMYFUNCTION("""COMPUTED_VALUE"""),"P-3 Origin Logistic hard approved ✅") -> P-3 Origin Logistic hard approved ✅ | BB2: =IFERROR(__xludf.DUMMYFUNCTION("""COMPUTED_VALUE"""),"P-3 PGM Hard copy approval") -> P-3 PGM Hard copy approval
C3: =IFERROR(__xludf.DUMMYFUNCTION("""COMPUTED_VALUE"""),"Example") -> Example | D3: =IFERROR(__xludf.DUMMYFUNCTION("""COMPUTED_VALUE"""),"MP") -> MP | E3: =IFERROR(__xludf.DUMMYFUNCTION("""COMPUTED_VALUE"""),"Pristine") -> Pristine | F3: =IFERROR(__xludf.DUMMYFUNCTION("""COMPUTED_VALUE"""),"GA03523-US") -> GA03523-US | H3: =IFERROR(__xludf.DUMMYFUNCTION("""COMPUTED_VALUE"""),8.10029936316E11) -> 810029936316 | J3: =IFERROR(__xludf.DUMMYFUNCTION("""COMPUTED_VALUE"""),"no") -> no | K3: =IFERROR(__xludf.DUMMYFUNCTION("""COMPUTED_VALUE"""),"VZN Master Carton Label") -> VZN Master Carton Label | M3: =IFERROR(__xludf.DUMMYFUNCTION("""COMPUTED_VALUE"""),"VZN Pallet Label -> BTO(EDI) VZN Pallet Label -> BTS(Normal case) ") -> VZN Pallet Label -> BTO(EDI) VZN Pallet Label -> BTS(Normal case) | O3: =IFERROR(__xludf.DUMMYFUNCTION("""COMPUTED_VALUE"""),"G952-03249-00") -> G952-03249-00 | P3: =IFERROR(__xludf.DUMMYFUNCTION("""COMPUTED_VALUE"""),"A") -> A | Q3: =IFERROR(__xludf.DUMMYFUNCTION("""COMPUTED_VALUE"""),"128GB") -> 128GB | S3: =IFERROR(__xludf.DUMMYFUNCTION("""COMPUTED_VALUE"""),"Obsidian") -> Obsidian | T3: =IFERROR(__xludf.DUMMYFUNCTION("""COMPUTED_VALUE"""),"US-VZW") -> US-VZW | U3: =IFERROR(__xludf.DUMMYFUNCTION("""COMPUTED_VALUE"""),"Pixel 7, Obsidian, 128GB, VZW") -> Pixel 7, Obsidian, 128GB, VZW | W3: =IFERROR(__xludf.DUMMYFUNCTION("""COMPUTED_VALUE"""),"#NUM!") -> #NUM! | X3: =IFERROR(__xludf.DUMMYFUNCTION("""COMPUTED_VALUE"""),45291.0) -> 45291 | Y3: =IFERROR(__xludf.DUMMYFUNCTION("""COMPUTED_VALUE"""),45240.0) -> 45240 | Z3: =IFERROR(__xludf.DUMMYFUNCTION("""COMPUTED_VALUE"""),TRUE) -> TRUE | AA3: =IFERROR(__xludf.DUMMYFUNCTION("""COMPUTED_VALUE"""),45240.0) -> 45240 | AB3: =IFERROR(__xludf.DUMMYFUNCTION("""COMPUTED_VALUE"""),TRUE) -> TRUE | AC3: =IFERROR(__xludf.DUMMYFUNCTION("""COMPUTED_VALUE"""),45247.0) -> 45247 | AD3: =IFERROR(__xludf.DUMMYFUNCTION("""COMPUTED_VALUE"""),45247.0) -> 45247 | AE3: =IFERROR(__xludf.DUMMYFUNCTION("""COMPUTED_VALUE"""),"GA03523-US") -> GA03523-US | AG3: =IFERROR(__xludf.DUMMYFUNCTION("""COMPUTED_VALUE"""),"GA03523-US") -> GA03523-US | AI3: =IFERROR(__xludf.DUMMYFUNCTION("""COMPUTED_VALUE"""),"GA03523-US") -> GA03523-US | AJ3: =IFERROR(__xludf.DUMMYFUNCTION("""COMPUTED_VALUE"""),45253.0) -> 45253 | AK3: =IFERROR(__xludf.DUMMYFUNCTION("""COMPUTED_VALUE"""),45261.0) -> 45261 | AL3: =IFERROR(__xludf.DUMMYFUNCTION("""COMPUTED_VALUE"""),TRUE) -> TRUE | AN3: =IFERROR(__xludf.DUMMYFUNCTION("""COMPUTED_VALUE"""),45261.0) -> 45261 | AO3: =IFERROR(__xludf.DUMMYFUNCTION("""COMPUTED_VALUE"""),TRUE) -> TRUE | AP3: =IFERROR(__xludf.DUMMYFUNCTION("""COMPUTED_VALUE"""),"N") -> N | AQ3: =IFERROR(__xludf.DUMMYFUNCTION("""COMPUTED_VALUE"""),"-") -> - | AV3: =IFERROR(__xludf.DUMMYFUNCTION("""COMPUTED_VALUE"""),45261.0) -> 45261 | AX3: =IFERROR(__xludf.DUMMYFUNCTION("""COMPUTED_VALUE"""),"N") -> N | AZ3: =IFERROR(__xludf.DUMMYFUNCTION("""COMPUTED_VALUE"""),45287.0) -> 45287 | BA3: =IFERROR(__xludf.DUMMYFUNCTION("""COMPUTED_VALUE"""),TRUE) -> TRUE | BB3: =IFERROR(__xludf.DUMMYFUNCTION("""COMPUTED_VALUE"""),45287.0) -> 45287
C4: =IFERROR(__xludf.DUMMYFUNCTION("""COMPUTED_VALUE"""),"Example") -> Example | D4: =IFERROR(__xludf.DUMMYFUNCTION("""COMPUTED_VALUE"""),"MP") -> MP | E4: =IFERROR(__xludf.DUMMYFUNCTION("""COMPUTED_VALUE"""),"Pristine") -> Pristine | F4: =IFERROR(__xludf.DUMMYFUNCTION("""COMPUTED_VALUE"""),"GA03523-US") -> GA03523-US | H4: =IFERROR(__xludf.DUMMYFUNCTION("""COMPUTED_VALUE"""),8.10029936316E11) -> 810029936316 | J4: =IFERROR(__xludf.DUMMYFUNCTION("""COMPUTED_VALUE"""),"no") -> no | O4: =IFERROR(__xludf.DUMMYFUNCTION("""COMPUTED_VALUE"""),"G952-03249-00") -> G952-03249-00 | P4: =IFERROR(__xludf.DUMMYFUNCTION("""COMPUTED_VALUE"""),"A") -> A | Q4: =IFERROR(__xludf.DUMMYFUNCTION("""COMPUTED_VALUE"""),"128GB") -> 128GB | S4: =IFERROR(__xludf.DUMMYFUNCTION("""COMPUTED_VALUE"""),"Obsidian") -> Obsidian | T4: =IFERROR(__xludf.DUMMYFUNCTION("""COMPUTED_VALUE"""),"US-VZW") -> US-VZW | U4: =IFERROR(__xludf.DUMMYFUNCTION("""COMPUTED_VALUE"""),"Pixel 7, Obsidian, 128GB, VZW") -> Pixel 7, Obsidian, 128GB, VZW | W4: =IFERROR(__xludf.DUMMYFUNCTION("""COMPUTED_VALUE"""),"#NUM!") -> #NUM! | X4: =IFERROR(__xludf.DUMMYFUNCTION("""COMPUTED_VALUE"""),45239.0) -> 45239 | Y4: =IFERROR(__xludf.DUMMYFUNCTION("""COMPUTED_VALUE"""),45188.0) -> 45188 | Z4: =IFERROR(__xludf.DUMMYFUNCTION("""COMPUTED_VALUE"""),FALSE) -> FALSE | AA4: =IFERROR(__xludf.DUMMYFUNCTION("""COMPUTED_VALUE"""),45188.0) -> 45188 | AB4: =IFERROR(__xludf.DUMMYFUNCTION("""COMPUTED_VALUE"""),FALSE) -> FALSE | AC4: =IFERROR(__xludf.DUMMYFUNCTION("""COMPUTED_VALUE"""),45195.0) -> 45195 | AD4: =IFERROR(__xludf.DUMMYFUNCTION("""COMPUTED_VALUE"""),45195.0) -> 45195 | AE4: =IFERROR(__xludf.DUMMYFUNCTION("""COMPUTED_VALUE"""),"GA03523-US") -> GA03523-US | AG4: =IFERROR(__xludf.DUMMYFUNCTION("""COMPUTED_VALUE"""),"GA03523-US") -> GA03523-US | AJ4: =IFERROR(__xludf.DUMMYFUNCTION("""COMPUTED_VALUE"""),45201.0) -> 45201 | AK4: =IFERROR(__xludf.DUMMYFUNCTION("""COMPUTED_VALUE"""),45209.0) -> 45209 | AL4: =IFERROR(__xludf.DUMMYFUNCTION("""COMPUTED_VALUE"""),FALSE) -> FALSE | AN4: =IFERROR(__xludf.DUMMYFUNCTION("""COMPUTED_VALUE"""),45209.0) -> 45209 | AO4: =IFERROR(__xludf.DUMMYFUNCTION("""COMPUTED_VALUE"""),FALSE) -> FALSE | AP4: =IFERROR(__xludf.DUMMYFUNCTION("""COMPUTED_VALUE"""),"Y") -> Y | AV4: =IFERROR(__xludf.DUMMYFUNCTION("""COMPUTED_VALUE"""),45209.0) -> 45209 | AX4: =IFERROR(__xludf.DUMMYFUNCTION("""COMPUTED_VALUE"""),"Y") -> Y | AY4: =IFERROR(__xludf.DUMMYFUNCTION("""COMPUTED_VALUE"""),"-") -> - | AZ4: =IFERROR(__xludf.DUMMYFUNCTION("""COMPUTED_VALUE"""),45235.0) -> 45235 | BA4: =IFERROR(__xludf.DUMMYFUNCTION("""COMPUTED_VALUE"""),TRUE) -> TRUE | BB4: =IFERROR(__xludf.DUMMYFUNCTION("""COMPUTED_VALUE"""),45235.0) -> 45235
W5: =IFERROR(__xludf.DUMMYFUNCTION("""COMPUTED_VALUE"""),"#NUM!") -> #NUM! | Y5: =IFERROR(__xludf.DUMMYFUNCTION("""COMPUTED_VALUE"""),"#VALUE!") -> #VALUE! | Z5: =IFERROR(__xludf.DUMMYFUNCTION("""COMPUTED_VALUE"""),FALSE) -> FALSE | AA5: =IFERROR(__xludf.DUMMYFUNCTION("""COMPUTED_VALUE"""),"#VALUE!") -> #VALUE! | AB5: =IFERROR(__xludf.DUMMYFUNCTION("""COMPUTED_VALUE"""),FALSE) -> FALSE | AC5: =IFERROR(__xludf.DUMMYFUNCTION("""COMPUTED_VALUE"""),"#VALUE!") -> #VALUE! | AD5: =IFERROR(__xludf.DUMMYFUNCTION("""COMPUTED_VALUE"""),"#VALUE!") -> #VALUE! | AJ5: =IFERROR(__xludf.DUMMYFUNCTION("""COMPUTED_VALUE"""),"#VALUE!") -> #VALUE! | AK5: =IFERROR(__xludf.DUMMYFUNCTION("""COMPUTED_VALUE"""),"#VALUE!") -> #VALUE! | AL5: =IFERROR(__xludf.DUMMYFUNCTION("""COMPUTED_VALUE"""),FALSE) -> FALSE | AN5: =IFERROR(__xludf.DUMMYFUNCTION("""COMPUTED_VALUE"""),"#VALUE!") -> #VALUE! | AO5: =IFERROR(__xludf.DUMMYFUNCTION("""COMPUTED_VALUE"""),FALSE) -> FALSE | AV5: =IFERROR(__xludf.DUMMYFUNCTION("""COMPUTED_VALUE"""),"#VALUE!") -> #VALUE! | AZ5: =IFERROR(__xludf.DUMMYFUNCTION("""COMPUTED_VALUE"""),"#VALUE!") -> #VALUE! | BA5: =IFERROR(__xludf.DUMMYFUNCTION("""COMPUTED_VALUE"""),FALSE) -> FALSE | BB5: =IFERROR(__xludf.DUMMYFUNCTION("""COMPUTED_VALUE"""),"#VALUE!") -> #VALUE!
A6: =MID(M6, FIND(CHAR(10), M6) + 1, LEN(M6) - FIND(CHAR(10), M6)) -> G990-08499-11-A | B6: =MID(O6, FIND(CHAR(10), O6) + 1, LEN(O6) - FIND(CHAR(10), O6)) -> G990-08493-00-A | C6: =IFERROR(__xludf.DUMMYFUNCTION("""COMPUTED_VALUE"""),"GSTORE") -> GSTORE | D6: =IFERROR(__xludf.DUMMYFUNCTION("""COMPUTED_VALUE"""),"MP") -> MP | E6: =IFERROR(__xludf.DUMMYFUNCTION("""COMPUTED_VALUE"""),"Pristine") -> Pristine | F6: =IFERROR(__xludf.DUMMYFUNCTION("""COMPUTED_VALUE"""),"GA09887-US") -> GA09887-US | G6: =IFERROR(__xludf.DUMMYFUNCTION("""COMPUTED_VALUE"""),"G4QUR") -> G4QUR | H6: =IFERROR(__xludf.DUMMYFUNCTION("""COMPUTED_VALUE"""),8.40353925823E11) -> 840353925823 | I6: =IFERROR(__xludf.DUMMYFUNCTION("""COMPUTED_VALUE"""),"0840353925823") -> 0840353925823 | K6: =IFERROR(__xludf.DUMMYFUNCTION("""COMPUTED_VALUE"""),"ROW Master Carton Label (UPC)") -> ROW Master Carton Label (UPC) | L6: =IFERROR(__xludf.DUMMYFUNCTION("""COMPUTED_VALUE"""),"Standard Pallet Label -> BTO(EDI) Standard Pallet Label -> BTS(Normal case)") -> Standard Pallet Label -> BTO(EDI) Standard Pallet Label -> BTS(Normal case) | M6: =IFERROR(__xludf.DUMMYFUNCTION("""COMPUTED_VALUE"""),"G990-08499-11-02 G990-08499-11-A") -> G990-08499-11-02 G990-08499-11-A | N6: =IFERROR(__xludf.DUMMYFUNCTION("""COMPUTED_VALUE"""),"N/A") -> N/A | O6: =IFERROR(__xludf.DUMMYFUNCTION("""COMPUTED_VALUE"""),"G990-08493-00-01 G990-08493-00-A") -> G990-08493-00-01 G990-08493-00-A | P6: =IFERROR(__xludf.DUMMYFUNCTION("""COMPUTED_VALUE"""),"BOB→A Retail→A") -> BOB→A Retail→A | Q6: =IFERROR(__xludf.DUMMYFUNCTION("""COMPUTED_VALUE"""),"128GB") -> 128GB | R6: =IFERROR(__xludf.DUMMYFUNCTION("""COMPUTED_VALUE"""),"Obsidian") -> Obsidian | S6: =IFERROR(__xludf.DUMMYFUNCTION("""COMPUTED_VALUE"""),"Midnight") -> Midnight | T6: =IFERROR(__xludf.DUMMYFUNCTION("""COMPUTED_VALUE"""),"US GStore") -> US GStore | U6: =IFERROR(__xludf.DUMMYFUNCTION("""COMPUTED_VALUE"""),"SKU,CLR1, GOOD, MMWAVE, US GSTORE, BZ5") -> SKU,CLR1, GOOD, MMWAVE, US GSTORE, BZ5 | W6: =IFERROR(__xludf.DUMMYFUNCTION("""COMPUTED_VALUE"""),"#NUM!") -> #NUM! | X6: =IFERROR(__xludf.DUMMYFUNCTION("""COMPUTED_VALUE"""),45831.0) -> 45831 | Y6: =IFERROR(__xludf.DUMMYFUNCTION("""COMPUTED_VALUE"""),45780.0) -> 45780 | Z6: =IFERROR(__xludf.DUMMYFUNCTION("""COMPUTED_VALUE"""),TRUE) -> TRUE | AA6: =IFERROR(__xludf.DUMMYFUNCTION("""COMPUTED_VALUE"""),45780.0) -> 45780 | AB6: =IFERROR(__xludf.DUMMYFUNCTION("""COMPUTED_VALUE"""),FALSE) -> FALSE | AC6: =IFERROR(__xludf.DUMMYFUNCTION("""COMPUTED_VALUE"""),45787.0) -> 45787 | AD6: =IFERROR(__xludf.DUMMYFUNCTION("""COMPUTED_VALUE"""),45787.0) -> 45787 | AE6: =IFERROR(__xludf.DUMMYFUNCTION("""COMPUTED_VALUE"""),"GA09887-US GA09887-US-RevA") -> GA09887-US GA09887-US-RevA | AG6: =IFERROR(__xludf.DUMMYFUNCTION("""COMPUTED_VALUE"""),"GA09887-US") -> GA09887-US | AH6: =IFERROR(__xludf.DUMMYFUNCTION("""COMPUTED_VALUE"""),"GA09887-US GA09887-US-RevA") -> GA09887-US GA09887-US-RevA | AI6: =IFERROR(__xludf.DUMMYFUNCTION("""COMPUTED_VALUE"""),"GA09887-US") -> GA09887-US | AJ6: =IFERROR(__xludf.DUMMYFUNCTION("""COMPUTED_VALUE"""),45793.0) -> 45793 | AK6: =IFERROR(__xludf.DUMMYFUNCTION("""COMPUTED_VALUE"""),45801.0) -> 45801 | AL6: =IFERROR(__xludf.DUMMYFUNCTION("""COMPUTED_VALUE"""),TRUE) -> TRUE | AM6: =IFERROR(__xludf.DUMMYFUNCTION("""COMPUTED_VALUE"""),TRUE) -> TRUE | AN6: =IFERROR(__xludf.DUMMYFUNCTION("""COMPUTED_VALUE"""),45801.0) -> 45801 | AO6: =IFERROR(__xludf.DUMMYFUNCTION("""COMPUTED_VALUE"""),TRUE) -> TRUE | AP6: =IFERROR(__xludf.DUMMYFUNCTION("""COMPUTED_VALUE"""),"N") -> N | AR6: =IFERROR(__xludf.DUMMYFUNCTION("""COMPUTED_VALUE"""),45801.0) -> 45801 | AS6: =IFERROR(__xludf.DUMMYFUNCTION("""COMPUTED_VALUE"""),TRUE) -> TRUE | AT6: =IFERROR(__xludf.DUMMYFUNCTION("""COMPUTED_VALUE"""),"N") -> N | AV6: =IFERROR(__xludf.DUMMYFUNCTION("""COMPUTED_VALUE"""),45801.0) -> 45801 | AW6: =IFERROR(__xludf.DUMMYFUNCTION("""COMPUTED_VALUE"""),FALSE) -> FALSE | AZ6: =IFERROR(__xludf.DUMMYFUNCTION("""COMPUTED_VALUE"""),45827.0) -> 45827 | BA6: =IFERROR(__xludf.DUMMYFUNCTION("""COMPUTED_VALUE"""),FALSE) -> FALSE | BB6: =IFERROR(__xludf.DUMMYFUNCTION("""COMPUTED_VALUE"""),45827.0) -> 45827
